<?xml version="1.0" ?>
<!-- =================================================================================== -->
<!-- |    This document was autogenerated by xacro from urdf/mantis.xacro              | -->
<!-- |    EDITING THIS FILE BY HAND IS NOT RECOMMENDED                                 | -->
<!-- =================================================================================== -->
<robot name="motoman_vacumm" xmlns:xacro="http://ros.org/wiki/xacro">
  <!-- instantiating arm and gripper -->
  <link name="base_link">
    <visual>
      <geometry>
        <mesh filename="package://motoman_config/meshes/sia20d/visual/MOTOMAN_BASE.stl"/>
      </geometry>
      <material name="blue">
        <color rgba="0 0 1 1"/>
      </material>
    </visual>
    <collision>
      <geometry>
        <mesh filename="package://motoman_config/meshes/sia20d/collision/MOTOMAN_BASE.stl"/>
      </geometry>
      <material name="yellow">
        <color rgba="0 1 1 1"/>
      </material>
    </collision>
  </link>
  <link name="link_s">
    <visual>
      <origin rpy="0 0 3.1416" xyz="0 0 0"/>
      <geometry>
        <mesh filename="package://motoman_config/meshes/sia20d/visual/MOTOMAN_AXIS_S.stl"/>
      </geometry>
      <material name="silver">
        <color rgba="0.8 0.8 0.8 1"/>
      </material>
    </visual>
    <collision>
      <origin rpy="0 0 3.1416" xyz="0 0 0"/>
      <geometry>
        <mesh filename="package://motoman_config/meshes/sia20d/collision/MOTOMAN_AXIS_S.stl"/>
      </geometry>
      <material name="yellow"/>
    </collision>
  </link>
  <link name="link_l">
    <visual>
      <origin rpy="1.57 3.1416 3.1416" xyz="0 0 0"/>
      <geometry>
        <mesh filename="package://motoman_config/meshes/sia20d/visual/MOTOMAN_AXIS_L.stl"/>
      </geometry>
      <material name="blue"/>
    </visual>
    <collision>
      <origin rpy="1.57 3.1416 3.1416" xyz="0 0 0"/>
      <geometry>
        <mesh filename="package://motoman_config/meshes/sia20d/collision/MOTOMAN_AXIS_L.stl"/>
      </geometry>
      <material name="yellow"/>
    </collision>
  </link>
  <link name="link_e">
    <visual>
      <origin rpy="0 0 0" xyz="0 0 0"/>
      <geometry>
        <mesh filename="package://motoman_config/meshes/sia20d/visual/MOTOMAN_AXIS_E.stl"/>
      </geometry>
      <material name="silver"/>
    </visual>
    <collision>
      <origin rpy="0 0 0" xyz="0 0 0"/>
      <geometry>
        <mesh filename="package://motoman_config/meshes/sia20d/collision/MOTOMAN_AXIS_E.stl"/>
      </geometry>
      <material name="yellow"/>
    </collision>
  </link>
  <link name="link_u">
    <visual>
      <origin rpy="1.57 -3.1415 3.1416" xyz="0 0 0"/>
      <geometry>
        <mesh filename="package://motoman_config/meshes/sia20d/visual/MOTOMAN_AXIS_U.stl"/>
      </geometry>
      <material name="blue"/>
    </visual>
    <collision>
      <origin rpy="1.57 -3.1415 3.1416" xyz="0 0 0"/>
      <geometry>
        <mesh filename="package://motoman_config/meshes/sia20d/collision/MOTOMAN_AXIS_U.stl"/>
      </geometry>
      <material name="yellow"/>
    </collision>
  </link>
  <link name="link_r">
    <visual>
      <origin rpy="0 0 0" xyz="0 0 0"/>
      <geometry>
        <mesh filename="package://motoman_config/meshes/sia20d/visual/MOTOMAN_AXIS_R.stl"/>
      </geometry>
      <material name="silver"/>
    </visual>
    <collision>
      <origin rpy="0 0 0" xyz="0 0 0"/>
      <geometry>
        <mesh filename="package://motoman_config/meshes/sia20d/collision/MOTOMAN_AXIS_R.stl"/>
      </geometry>
      <material name="yellow"/>
    </collision>
  </link>
  <link name="link_b">
    <visual>
      <origin rpy="-1.57 0 0" xyz="0 0 0"/>
      <geometry>
        <mesh filename="package://motoman_config/meshes/sia20d/visual/MOTOMAN_AXIS_B.stl"/>
      </geometry>
      <material name="blue"/>
    </visual>
    <collision>
      <origin rpy="-1.57 0 0" xyz="0 0 0"/>
      <geometry>
        <mesh filename="package://motoman_config/meshes/sia20d/collision/MOTOMAN_AXIS_B.stl"/>
      </geometry>
      <material name="yellow"/>
    </collision>
  </link>
  <link name="link_t">
    <visual>
      <geometry>
        <mesh filename="package://motoman_config/meshes/sia20d/visual/MOTOMAN_AXIS_T.stl"/>
      </geometry>
      <material name="silver"/>
    </visual>
    <collision>
      <geometry>
        <mesh filename="package://motoman_config/meshes/sia20d/collision/MOTOMAN_AXIS_T.stl"/>
      </geometry>
      <material name="yellow"/>
    </collision>
  </link>
  <joint name="joint_s" type="revolute">
    <parent link="base_link"/>
    <child link="link_s"/>
    <origin rpy="0 0 0" xyz="0 0 0.41"/>
    <axis xyz="0 0 1"/>
    <limit effort="100" lower="-3.1416" upper="3.1416" velocity="2.26"/>
  </joint>
  <joint name="joint_l" type="revolute">
    <parent link="link_s"/>
    <child link="link_l"/>
    <origin rpy="0 0 0" xyz="0 0 0"/>
    <axis xyz="0 1 0"/>
    <limit effort="100" lower="-1.91" upper="1.91" velocity="2.26"/>
  </joint>
  <joint name="joint_e" type="revolute">
    <parent link="link_l"/>
    <child link="link_e"/>
    <origin rpy="0 0 0" xyz="0 0 0.49"/>
    <axis xyz="0 0 1"/>
    <limit effort="100" lower="-2.96" upper="2.96" velocity="2.96"/>
  </joint>
  <joint name="joint_u" type="revolute">
    <parent link="link_e"/>
    <child link="link_u"/>
    <origin rpy="0 0 0" xyz="0 0 0"/>
    <axis xyz="0 -1 0"/>
    <limit effort="100" lower="-2.26" upper="2.26" velocity="2.96"/>
  </joint>
  <joint name="joint_r" type="revolute">
    <parent link="link_u"/>
    <child link="link_r"/>
    <origin rpy="0 0 0" xyz="0 0 0.420"/>
    <axis xyz="0 0 -1"/>
    <limit effort="100" lower="-3.1416" upper="3.1416" velocity="3.48"/>
  </joint>
  <joint name="joint_b" type="revolute">
    <parent link="link_r"/>
    <child link="link_b"/>
    <origin rpy="0 0 0" xyz="0 0 0"/>
    <axis xyz="0 -1 0"/>
    <limit effort="100" lower="-1.91" upper="1.91" velocity="3.48"/>
  </joint>
  <joint name="joint_t" type="revolute">
    <parent link="link_b"/>
    <child link="link_t"/>
    <origin rpy="0 0 0" xyz="0 0 0.18"/>
    <axis xyz="0 0 -1"/>
    <limit effort="100" lower="-3.1416" upper="3.1416" velocity="6.97"/>
  </joint>
  <link name="palm">
    <visual>
      <origin rpy="0 0 0" xyz="0 0.036 -0.1"/>
      <geometry>
        <mesh filename="package://mantis_config/config/meshes/vacuum_gripper.STL"/>
      </geometry>
      <material name="silver">
        <color rgba="0.8 0.8 0.8 1"/>
      </material>
    </visual>
    <collision>
      <origin rpy="0 0 0" xyz="0 0.036 -0.1"/>
      <geometry>
        <mesh filename="package://mantis_config/config/meshes/vacuum_gripper.stl"/>
      </geometry>
      <material name="another_blue2">
        <color rgba="0.38 0.54 0.83 1"/>
      </material>
    </collision>
  </link>
  <!-- property list -->
  <!-- link sub-blocks -->
  <!-- arm-gripper coupling links -->
  <link name="coupler">
    <visual>
      <geometry>
        <mesh filename="package://longhorn/meshes/coupler/visual/COUPLER.stl"/>
      </geometry>
      <material name="orange">
        <color rgba="1 0.5 0 1"/>
      </material>
    </visual>
    <collision>
      <geometry>
        <mesh filename="package://longhorn/meshes/coupler/collision/COUPLER.stl"/>
      </geometry>
      <material name="yellow">
        <color rgba="0 1 1 1"/>
      </material>
    </collision>
  </link>
  <!-- end of arm-gripper coupling links -->
  <!-- arm-gripper coupling joints -->
  <joint name="tool-coupler" type="fixed">
    <parent link="link_t"/>
    <child link="coupler"/>
    <origin rpy="1.570 0 -0.785" xyz="0 0 0"/>
  </joint>
  <joint name="coupler-hand" type="fixed">
    <parent link="coupler"/>
    <child link="palm"/>
    <origin rpy="-1.570 0 0" xyz="0 0.182 0.036"/>
  </joint>
  <!-- end of arm-gripper coupling joints -->
  <!-- environment objects -->
  <link name="table">
    <visual>
      <geometry>
        <box size="1.83 2.44 0.25"/>
      </geometry>
      <material name="">
        <color rgba="1 0 1 1"/>
      </material>
    </visual>
    <collision>
      <geometry>
        <box size="1.83 2.44 0.25"/>
      </geometry>
      <material name="">
        <color rgba="1 0 1 1"/>
      </material>
    </collision>
  </link>
  <link name="table_keepout_1">
    <collision>
      <geometry>
        <box size="2.08 0.25 2"/>
      </geometry>
      <material name="">
        <color rgba="1 0.2 1 0.1"/>
      </material>
    </collision>
  </link>
  <link name="table_keepout_2">
    <collision>
      <geometry>
        <box size="0.25 2.69 2"/>
      </geometry>
      <material name="">
        <color rgba="1 0.2 1 0.1"/>
      </material>
    </collision>
  </link>
  <link name="power_supply">
    <visual>
      <geometry>
        <box size="0.400 0.250 0.115"/>
      </geometry>
      <material name="">
        <color rgba="1 0.2 1 0.1"/>
      </material>
    </visual>
    <collision>
      <geometry>
        <box size="0.400 0.250 0.115"/>
      </geometry>
      <material name="">
        <color rgba="1 0.2 1 0.1"/>
      </material>
    </collision>
  </link>
  <link name="kinect_keepout">
    <collision>
      <geometry>
        <box size="0.25 2.69 2"/>
      </geometry>
      <material name="">
        <color rgba="1 0.2 1 0.1"/>
      </material>
    </collision>
  </link>
  <link name="kinect">
    <collision>
      <geometry>
        <box size="0.36 0.28 0.22"/>
      </geometry>
      <material name="">
        <color rgba="1 0.8 1 0.1"/>
      </material>
    </collision>
  </link>
  <!-- end of environment objects -->
  <!-- environment joints -->
  <joint name="base-table" type="fixed">
    <parent link="base_link"/>
    <child link="table"/>
    <origin rpy="0 0 -0.785" xyz="1.19 0.22 -0.125"/>
  </joint>
  <joint name="base-kinect" type="fixed">
    <parent link="base_link"/>
    <child link="kinect"/>
    <origin rpy="0 1.25 3.13" xyz="1.14 -0.055 1.5"/>
  </joint> 
<!--	<link name="kinect1">
		<visual>
			<origin rpy="0 0 0" xyz="0 0 0"/>
			<geometry>
				<sphere radius="0.0005"/>
			</geometry>
		</visual>
	</link>
	<link name="kinect2">
		<visual>
			<origin rpy="0 0 0" xyz="0 0 0"/>
			<geometry>
				<sphere radius="0.0005"/>
			</geometry>
		</visual>
	</link>
	<link name="kinect3">
		<visual>
			<origin rpy="0 0 0" xyz="0 0 0"/>
			<geometry>
				<sphere radius="0.0005"/>
			</geometry>
		</visual>
	</link>
	<link name="kinect4">
		<visual>
			<origin rpy="0 0 0" xyz="0 0 0"/>
			<geometry>
				<sphere radius="0.0005"/>
			</geometry>
		</visual>
	</link>
	<link name="kinect5">
		<visual>
			<origin rpy="0 0 0" xyz="0 0 0"/>
			<geometry>
				<sphere radius="0.0005"/>
			</geometry>
		</visual>
	</link>
	<link name="kinect6">
		<visual>
			<origin rpy="0 0 0" xyz="0 0 0"/>
			<geometry>
				<sphere radius="0.0005"/>
			</geometry>
		</visual>
	</link>
  <joint name="base-kinect1-z" type="prismatic"> 
    <parent link="base_link"/>
    <child link="kinect1"/>
    <origin rpy="0 0 0" xyz="0 0 1.5"/>
    <axis xyz="0 0 1"/>
    <limit effort="100" lower="-0.25" upper="0.25" velocity="3.48"/>
  </joint>
  <joint name="kinect1-kinect2-y" type="prismatic">
    <parent link="kinect1"/>
    <child link="kinect2"/>
    <origin rpy="0 0 0" xyz="0 -0.055 0"/>
    <axis xyz="0 1 0"/>
    <limit effort="100" lower="-0.1" upper="0.1" velocity="3.48"/>
  </joint>
  <joint name="kinect2-kinect3-x" type="prismatic">
    <parent link="kinect2"/>
    <child link="kinect3"/>
    <origin rpy="0 0 0" xyz="1.14 0 0"/>
    <axis xyz="1 0 0"/>
    <limit effort="100" lower="-0.15" upper="0.15" velocity="3.48"/>
  </joint>
  <joint name="kinect3-kinect4-y" type="revolute">
    <parent link="kinect3"/>
    <child link="kinect4"/>
    <origin rpy="0 0 3.13" xyz="0 0 0"/>
    <axis xyz="0 0 1"/>
    <limit effort="100" lower="-0.52" upper="0.52" velocity="3.48"/>
  </joint>
  <joint name="kinect4-kinect5-p" type="revolute">
    <parent link="kinect4"/>
    <child link="kinect5"/>
    <origin rpy="0 1.25 0" xyz="0 0 0"/>
    <axis xyz="0 1 0"/>
    <limit effort="100" lower="-0.52" upper="0.52" velocity="3.48"/>
  </joint>
  <joint name="kinect5-kinect6-r" type="revolute">
    <parent link="kinect5"/>
    <child link="kinect6"/>
    <origin rpy="0 0 0" xyz="0 0 0"/>
    <axis xyz="1 0 0"/>
    <limit effort="100" lower="-0.1" upper="0.1" velocity="3.48"/>
  </joint>
  <joint name="kinect6-kinect" type="revolute">
    <parent link="kinect6"/>
    <child link="kinect"/>
    <origin rpy="0 0 0" xyz="0 0 0"/>
    <axis xyz="1 0 0"/>
    <limit effort="100" lower="-0.1" upper="0.1" velocity="3.48"/>
  </joint> -->
<!-- END EXPERIMENT base_link to kinect-->
  <joint name="table-keepout_1" type="fixed">
    <parent link="table"/>
    <child link="table_keepout_1"/>
    <origin rpy="0 0 0" xyz="0 -1.34 1"/>
  </joint>
  <joint name="table-keepout_2" type="fixed">
    <parent link="table"/>
    <child link="table_keepout_2"/>
    <origin rpy="0 0 0" xyz="-1.025 0 1"/>
  </joint>
  <joint name="base-power_supply" type="fixed">
    <parent link="base_link"/>
    <child link="power_supply"/>
    <origin rpy="0 0 0" xyz="0 -0.260 0.050"/>
  </joint>
  <joint name="table-kinect" type="fixed">
    <parent link="table"/>
    <child link="kinect_keepout"/>
    <origin rpy="0 0 0" xyz=".5 0 1"/>
  </joint>
  <!-- end of environment joints -->
  <!-- sensor links -->
  <link name="kinect_frame">
    <visual>
      <origin rpy="0 0 0" xyz="0 0 0"/>
      <geometry>
        <box size="0.064 0.28 0.04"/>
      </geometry>
      <material name="silver"/>
    </visual>
    <collision>
      <origin rpy="0 0 0" xyz="0 0 0"/>
      <geometry>
        <box size="0.064 0.28 0.04"/>
      </geometry>
    </collision>
  </link>
  <link name="kinect_ir_link">
    <visual>
      <origin rpy="0 0 0" xyz="0 0 0"/>
      <geometry>
        <sphere radius="0.0005"/>
      </geometry>
    </visual>
  </link>
  <link name="kinect_rgb_link">
    <visual>
      <origin rpy="0 0 0" xyz="0 0 0"/>
      <geometry>
        <sphere radius="0.0005"/>
      </geometry>
    </visual>
  </link>
  <link name="kinect_ir_optical_frame"/>
  <link name="kinect_rgb_optical_frame"/>
  <!-- end of sensor links -->
  <!-- sensor joints -->
  <joint name="kinect_frame_joint" type="fixed">
    <parent link="kinect"/>
    <child link="kinect_frame"/>
    <origin rpy="0 0 0" xyz="0 0 0"/>
  </joint>
  <joint name="kinect_ir_joint" type="fixed">
    <parent link="kinect_frame"/>
    <child link="kinect_ir_link"/>
    <origin rpy="0 0 0" xyz="0 0 0"/>
  </joint>
  <joint name="kinect_ir_optical_frame_joint" type="fixed">
    <parent link="kinect_ir_link"/>
    <child link="kinect_ir_optical_frame"/>
    <origin rpy="-1.57 0 -1.57" xyz="0 0 0"/>
  </joint>
  <joint name="kinect_rgb_joint" type="fixed">
    <parent link="kinect_ir_link"/>
    <child link="kinect_rgb_link"/>
    <origin rpy="0 0 0" xyz="0 -0.03 0"/>
  </joint>
  <joint name="kinect_rgb_optical_frame_joint" type="fixed">
    <parent link="kinect_rgb_link"/>
    <child link="kinect_rgb_optical_frame"/>
    <origin rpy="-1.57 0 -1.57" xyz="0 0 0"/>
  </joint>
  <!-- end of sensor joints -->
</robot>

