<?xml version="1.0" ?>
<!-- =================================================================================== -->
<!-- |    This document was autogenerated by xacro from urdf/mantis_sia20d_arm_workspace.xacro | -->
<!-- |    EDITING THIS FILE BY HAND IS NOT RECOMMENDED                                 | -->
<!-- =================================================================================== -->
<robot name="mantis_sia20d" xmlns:xacro="http://ros.org/wiki/xacro">
  <material name="yellow_transparent">
    <color rgba="0 1 1 0.4"/>
  </material>
  <material name="orange_transparent">
    <color rgba="1 0.5 0 0.4"/>
  </material>
  <material name="gray_transparent">
    <color rgba="0.6 0.6 0.6 0.4"/>
  </material>
  <material name="blue_transparent">
    <color rgba="0 0.8 1 0.4"/>
  </material>
  <link name="workcell_frame"/>
  <!-- property list -->
  <!--xacro:property name="arm1_prefix" value=""/-->
  <!-- instantiating workcell definitions -->
  <link name="table_base1">
    <visual>
      <origin rpy="0 0 0" xyz="0 0 -0.5"/>
      <geometry>
        <box size="1.3875 2.22 1"/>
      </geometry>
      <material name="orange_transparent"/>
    </visual>
    <collision>
      <origin rpy="0 0 0" xyz="0 0 -0.5"/>
      <geometry>
        <box size="1.3875 2.22 1"/>
      </geometry>
      <material name="blue_transparent"/>
    </collision>
  </link>
  <joint name="workcell_to_table_base1" type="fixed">
    <parent link="workcell_frame"/>
    <child link="table_base1"/>
    <origin rpy="0 0 0" xyz="0.69375 0 0"/>
  </joint>
  <link name="front_wall1">
    <visual>
      <geometry>
        <box size="0.1 2.22 1"/>
      </geometry>
      <material name="gray_transparent"/>
    </visual>
    <collision>
      <geometry>
        <box size="0.1 2.22 1"/>
      </geometry>
      <material name="blue_transparent"/>
    </collision>
  </link>
  <joint name="workcell_frame_to_front_wall1" type="fixed">
    <parent link="workcell_frame"/>
    <child link="front_wall1"/>
    <origin rpy="0 0 0" xyz="1.3375 0 0.5"/>
  </joint>
  <link name="back_wall1">
    <visual>
      <geometry>
        <box size="0.04 2.0 1"/>
      </geometry>
      <material name="gray_transparent"/>
    </visual>
    <collision>
      <geometry>
        <box size="0.04 2.0 1"/>
      </geometry>
      <material name="blue_transparent"/>
    </collision>
  </link>
  <joint name="workcell_frame_to_back_wall1" type="fixed">
    <parent link="workcell_frame"/>
    <child link="back_wall1"/>
    <origin rpy="0 0 0" xyz="0.02 0 0.5"/>
  </joint>
  <link name="left_wall1">
    <visual>
      <geometry>
        <box size="1.221 0.1 1"/>
      </geometry>
      <material name="gray_transparent"/>
    </visual>
    <collision>
      <geometry>
        <box size="1.221 0.1 1"/>
      </geometry>
      <material name="blue_transparent"/>
    </collision>
  </link>
  <joint name="workcell_frame_to_left_wall1" type="fixed">
    <parent link="workcell_frame"/>
    <child link="left_wall1"/>
    <origin rpy="0 0 0" xyz="0.687 1.06 0.5"/>
  </joint>
  <link name="right_wall1">
    <visual>
      <geometry>
        <box size="1.221 0.1 1"/>
      </geometry>
      <material name="gray_transparent"/>
    </visual>
    <collision>
      <geometry>
        <box size="1.221 0.1 1"/>
      </geometry>
      <material name="blue_transparent"/>
    </collision>
  </link>
  <joint name="workcell_frame_to_right_wall1" type="fixed">
    <parent link="workcell_frame"/>
    <child link="right_wall1"/>
    <origin rpy="0 0 0" xyz="0.687 -1.06 0.5"/>
  </joint>
  <!-- end of workcell definitions -->
  <!-- instantiating sensor definitions -->
  <!--xacro:sensor_definitions prefix="${arm1_prefix}" parent_link="workcell_frame" 
		x_val="1.20" y_val="0" z_val="0.4" pitch="0.5235" yaw="3.147"/-->
  <material name="sia20d_arm_color_b">
    <color rgba="0 0.8 1 0.4"/>
  </material>
  <material name="sia20d_arm_color_a">
    <color rgba="0.8 0.2 1 0.2"/>
  </material>
  <material name="sia20d_arm_silver">
    <color rgba="0.6 0.6 0.6 1"/>
  </material>
  <link name="sia20d_arm_kinect">
    <collision>
      <material name="sia20d_arm_color_a"/>
      <geometry>
        <box size="0.36 0.28 0.22"/>
      </geometry>
    </collision>
  </link>
  <link name="sia20d_arm_kinect_keepout">
    <collision>
      <material name="sia20d_arm_color_b"/>
      <geometry>
        <box size="0.2 0.32 0.9"/>
      </geometry>
    </collision>
  </link>
  <link name="sia20d_arm_kinect_frame">
    <visual>
      <origin rpy="0 0 0" xyz="0 0 0"/>
      <geometry>
        <box size="0.064 0.28 0.04"/>
      </geometry>
      <material name="sia20d_arm_silver"/>
    </visual>
    <collision>
      <origin rpy="0 0 0" xyz="0 0 0"/>
      <geometry>
        <box size="0.064 0.28 0.04"/>
      </geometry>
    </collision>
  </link>
  <link name="sia20d_arm_kinect_ir_link">
    <visual>
      <origin rpy="0 0 0" xyz="0 0 0"/>
      <geometry>
        <sphere radius="0.0005"/>
      </geometry>
    </visual>
  </link>
  <link name="sia20d_arm_kinect_rgb_link">
    <visual>
      <origin rpy="0 0 0" xyz="0 0 0"/>
      <geometry>
        <sphere radius="0.0005"/>
      </geometry>
    </visual>
  </link>
  <link name="sia20d_arm_kinect_ir_optical_frame"/>
  <link name="sia20d_arm_kinect_rgb_optical_frame"/>
  <joint name="sia20d_arm_kinect_frame_joint" type="fixed">
    <parent link="sia20d_arm_kinect"/>
    <child link="sia20d_arm_kinect_frame"/>
    <origin rpy="0 0 0" xyz="0 0 0"/>
  </joint>
  <joint name="sia20d_arm_kinect_ir_joint" type="fixed">
    <parent link="sia20d_arm_kinect_frame"/>
    <child link="sia20d_arm_kinect_ir_link"/>
    <origin rpy="0 0 0" xyz="0 0 0"/>
  </joint>
  <joint name="sia20d_arm_kinect_ir_optical_frame_joint" type="fixed">
    <parent link="sia20d_arm_kinect_ir_link"/>
    <child link="sia20d_arm_kinect_ir_optical_frame"/>
    <origin rpy="-1.57 0 -1.57" xyz="0 0 0"/>
  </joint>
  <joint name="sia20d_arm_kinect_rgb_joint" type="fixed">
    <parent link="sia20d_arm_kinect_ir_link"/>
    <child link="sia20d_arm_kinect_rgb_link"/>
    <origin rpy="0 0 0" xyz="0 -0.03 0"/>
  </joint>
  <joint name="sia20d_arm_kinect_rgb_optical_frame_joint" type="fixed">
    <parent link="sia20d_arm_kinect_rgb_link"/>
    <child link="sia20d_arm_kinect_rgb_optical_frame"/>
    <origin rpy="-1.57 0 -1.57" xyz="0 0 0"/>
  </joint>
  <joint name="sia20d_arm_sia20d_arm_base_link_to_kinect" type="fixed">
    <parent link="sia20d_arm_base_link"/>
    <child link="sia20d_arm_kinect"/>
    <origin rpy="0 0.5235 2.356" xyz="1.08 -0.72 0.82"/>
  </joint>
  <joint name="sia20d_arm_sia20d_arm_base_link_to_kinect_keepout" type="fixed">
    <parent link="sia20d_arm_base_link"/>
    <child link="sia20d_arm_kinect_keepout"/>
    <origin rpy="0 0 2.356" xyz="1.08 -0.72 0.45"/>
  </joint>
  <!-- end of sensor definitions -->
  <!-- instantiating arm and gripper -->
  <link name="sia20d_arm_palm">
    <visual>
      <origin rpy="0 0 0" xyz="0 0.036 -0.0473"/>
      <geometry>
        <box size="0.044 0.088 0.0946"/>
      </geometry>
      <material name="another_blue1">
        <color rgba="0.40 0.40 0.80 1"/>
      </material>
    </visual>
    <collision>
      <origin rpy="0 0 0" xyz="0 0.036 -0.0473"/>
      <geometry>
        <box size="0.044 0.088 0.0946"/>
      </geometry>
      <material name="another_blue2">
        <color rgba="0.38 0.54 0.83 1"/>
      </material>
    </collision>
  </link>
  <link name="sia20d_arm_base_link">
    <visual>
      <geometry>
        <mesh filename="package://motoman_config/meshes/sia20d/visual/MOTOMAN_BASE.stl"/>
      </geometry>
      <material name="blue">
        <color rgba="0 0 1 1"/>
      </material>
    </visual>
    <collision>
      <geometry>
        <mesh filename="package://motoman_config/meshes/sia20d/collision/MOTOMAN_BASE.stl"/>
      </geometry>
      <material name="yellow">
        <color rgba="0 1 1 1"/>
      </material>
    </collision>
  </link>
  <link name="sia20d_arm_link_s">
    <visual>
      <origin rpy="0 0 3.1416" xyz="0 0 0"/>
      <geometry>
        <mesh filename="package://motoman_config/meshes/sia20d/visual/MOTOMAN_AXIS_S.stl"/>
      </geometry>
      <material name="silver">
        <color rgba="0.8 0.8 0.8 1"/>
      </material>
    </visual>
    <collision>
      <origin rpy="0 0 3.1416" xyz="0 0 0"/>
      <geometry>
        <mesh filename="package://motoman_config/meshes/sia20d/collision/MOTOMAN_AXIS_S.stl"/>
      </geometry>
      <material name="yellow"/>
    </collision>
  </link>
  <link name="sia20d_arm_link_l">
    <visual>
      <origin rpy="1.57 3.1416 3.1416" xyz="0 0 0"/>
      <geometry>
        <mesh filename="package://motoman_config/meshes/sia20d/visual/MOTOMAN_AXIS_L.stl"/>
      </geometry>
      <material name="blue"/>
    </visual>
    <collision>
      <origin rpy="1.57 3.1416 3.1416" xyz="0 0 0"/>
      <geometry>
        <mesh filename="package://motoman_config/meshes/sia20d/collision/MOTOMAN_AXIS_L.stl"/>
      </geometry>
      <material name="yellow"/>
    </collision>
  </link>
  <link name="sia20d_arm_link_e">
    <visual>
      <origin rpy="0 0 0" xyz="0 0 0"/>
      <geometry>
        <mesh filename="package://motoman_config/meshes/sia20d/visual/MOTOMAN_AXIS_E.stl"/>
      </geometry>
      <material name="silver"/>
    </visual>
    <collision>
      <origin rpy="0 0 0" xyz="0 0 0"/>
      <geometry>
        <mesh filename="package://motoman_config/meshes/sia20d/collision/MOTOMAN_AXIS_E.stl"/>
      </geometry>
      <material name="yellow"/>
    </collision>
  </link>
  <link name="sia20d_arm_link_u">
    <visual>
      <origin rpy="1.57 -3.1415 3.1416" xyz="0 0 0"/>
      <geometry>
        <mesh filename="package://motoman_config/meshes/sia20d/visual/MOTOMAN_AXIS_U.stl"/>
      </geometry>
      <material name="blue"/>
    </visual>
    <collision>
      <origin rpy="1.57 -3.1415 3.1416" xyz="0 0 0"/>
      <geometry>
        <mesh filename="package://motoman_config/meshes/sia20d/collision/MOTOMAN_AXIS_U.stl"/>
      </geometry>
      <material name="yellow"/>
    </collision>
  </link>
  <link name="sia20d_arm_link_r">
    <visual>
      <origin rpy="0 0 0" xyz="0 0 0"/>
      <geometry>
        <mesh filename="package://motoman_config/meshes/sia20d/visual/MOTOMAN_AXIS_R.stl"/>
      </geometry>
      <material name="silver"/>
    </visual>
    <collision>
      <origin rpy="0 0 0" xyz="0 0 0"/>
      <geometry>
        <mesh filename="package://motoman_config/meshes/sia20d/collision/MOTOMAN_AXIS_R.stl"/>
      </geometry>
      <material name="yellow"/>
    </collision>
  </link>
  <link name="sia20d_arm_link_b">
    <visual>
      <origin rpy="-1.57 0 0" xyz="0 0 0"/>
      <geometry>
        <mesh filename="package://motoman_config/meshes/sia20d/visual/MOTOMAN_AXIS_B.stl"/>
      </geometry>
      <material name="blue"/>
    </visual>
    <collision>
      <origin rpy="-1.57 0 0" xyz="0 0 0"/>
      <geometry>
        <mesh filename="package://motoman_config/meshes/sia20d/collision/MOTOMAN_AXIS_B.stl"/>
      </geometry>
      <material name="yellow"/>
    </collision>
  </link>
  <link name="sia20d_arm_link_t">
    <visual>
      <geometry>
        <mesh filename="package://motoman_config/meshes/sia20d/visual/MOTOMAN_AXIS_T.stl"/>
      </geometry>
      <material name="silver"/>
    </visual>
    <collision>
      <geometry>
        <mesh filename="package://motoman_config/meshes/sia20d/collision/MOTOMAN_AXIS_T.stl"/>
      </geometry>
      <material name="yellow"/>
    </collision>
  </link>
  <joint name="joint_s" type="revolute">
    <parent link="sia20d_arm_base_link"/>
    <child link="sia20d_arm_link_s"/>
    <origin rpy="0 0 0" xyz="0 0 0.41"/>
    <axis xyz="0 0 1"/>
    <limit effort="100" lower="-3.1416" upper="3.1416" velocity="2.26"/>
  </joint>
  <joint name="joint_l" type="revolute">
    <parent link="sia20d_arm_link_s"/>
    <child link="sia20d_arm_link_l"/>
    <origin rpy="0 0 0" xyz="0 0 0"/>
    <axis xyz="0 1 0"/>
    <limit effort="100" lower="-1.91" upper="1.91" velocity="2.26"/>
  </joint>
  <joint name="joint_e" type="revolute">
    <parent link="sia20d_arm_link_l"/>
    <child link="sia20d_arm_link_e"/>
    <origin rpy="0 0 0" xyz="0 0 0.49"/>
    <axis xyz="0 0 1"/>
    <limit effort="100" lower="-2.96" upper="2.96" velocity="2.96"/>
  </joint>
  <joint name="joint_u" type="revolute">
    <parent link="sia20d_arm_link_e"/>
    <child link="sia20d_arm_link_u"/>
    <origin rpy="0 0 0" xyz="0 0 0"/>
    <axis xyz="0 -1 0"/>
    <limit effort="100" lower="-2.26" upper="2.26" velocity="2.96"/>
  </joint>
  <joint name="joint_r" type="revolute">
    <parent link="sia20d_arm_link_u"/>
    <child link="sia20d_arm_link_r"/>
    <origin rpy="0 0 0" xyz="0 0 0.420"/>
    <axis xyz="0 0 -1"/>
    <limit effort="100" lower="-3.1416" upper="3.1416" velocity="3.48"/>
  </joint>
  <joint name="joint_b" type="revolute">
    <parent link="sia20d_arm_link_r"/>
    <child link="sia20d_arm_link_b"/>
    <origin rpy="0 0 0" xyz="0 0 0"/>
    <axis xyz="0 -1 0"/>
    <limit effort="100" lower="-1.91" upper="1.91" velocity="3.48"/>
  </joint>
  <joint name="joint_t" type="revolute">
    <parent link="sia20d_arm_link_b"/>
    <child link="sia20d_arm_link_t"/>
    <origin rpy="0 0 0" xyz="0 0 0.18"/>
    <axis xyz="0 0 -1"/>
    <limit effort="100" lower="-3.1416" upper="3.1416" velocity="6.97"/>
  </joint>
  <!-- arm-workcell joint definitions -->
  <joint name="sia20d_to_workcell" type="fixed">
    <parent link="workcell_frame"/>
    <child link="sia20d_arm_base_link"/>
    <origin rpy="0 0 0" xyz="0.241 0 0"/>
  </joint>
  <!-- end of arm workcell joint definitions-->
  <!-- arm-gripper coupling link definitions-->
  <link name="sia20d_arm_coupler">
    <visual>
      <geometry>
        <mesh filename="package://longhorn/meshes/coupler/visual/COUPLER.stl"/>
      </geometry>
      <material name="orange">
        <color rgba="1 0.5 0 1"/>
      </material>
    </visual>
    <collision>
      <geometry>
        <mesh filename="package://longhorn/meshes/coupler/collision/COUPLER.stl"/>
      </geometry>
      <material name="yellow">
        <color rgba="0 1 1 1"/>
      </material>
    </collision>
  </link>
  <!-- end of arm-gripper coupling link definitions -->
  <!-- arm-gripper coupling joint definitions -->
  <joint name="tool-coupler" type="fixed">
    <parent link="sia20d_arm_link_t"/>
    <child link="sia20d_arm_coupler"/>
    <origin rpy="1.570 0 -0.785" xyz="0 0 0"/>
  </joint>
  <joint name="coupler-hand" type="fixed">
    <parent link="sia20d_arm_coupler"/>
    <child link="sia20d_arm_palm"/>
    <origin rpy="-1.570 0 0" xyz="0 0.182 0.036"/>
  </joint>
  <!-- end of arm-gripper coupling joint definitions -->
</robot>

