<?xml version="1.0" ?>
<!-- =================================================================================== -->
<!-- |    This document was autogenerated by xacro from urdf/mantis_ur5_arm_workspace.xacro | -->
<!-- |    EDITING THIS FILE BY HAND IS NOT RECOMMENDED                                 | -->
<!-- =================================================================================== -->
<robot name="mantis_ur5" xmlns:controller="http://playerstage.sourceforge.net/gazebo/xmlschema/#controller" xmlns:interface="http://playerstage.sourceforge.net/gazebo/xmlschema/#interface" xmlns:sensor="http://playerstage.sourceforge.net/gazebo/xmlschema/#sensor" xmlns:xacro="http://ros.org/wiki/xacro">
  <gazebo>
    <controller:gazebo_ros_controller_manager name="gazebo_ros_controller_manager" plugin="libgazebo_ros_controller_manager.so">
      <alwaysOn>true</alwaysOn>
      <updateRate>1000.0</updateRate>
      <interface:audio name="gazebo_ros_controller_manager_dummy_iface"/>
    </controller:gazebo_ros_controller_manager>
    <controller:gazebo_ros_power_monitor name="gazebo_ros_power_monitor_controller" plugin="libgazebo_ros_power_monitor.so">
      <alwaysOn>true</alwaysOn>
      <updateRate>1.0</updateRate>
      <timeout>5</timeout>
      <interface:audio name="power_monitor_dummy_interface"/>
      <powerStateTopic>power_state</powerStateTopic>
      <powerStateRate>10.0</powerStateRate>
      <fullChargeCapacity>87.78</fullChargeCapacity>
      <dischargeRate>-474</dischargeRate>
      <chargeRate>525</chargeRate>
      <dischargeVoltage>15.52</dischargeVoltage>
      <chargeVoltage>16.41</chargeVoltage>
    </controller:gazebo_ros_power_monitor>
  </gazebo>
  <material name="yellow_transparent">
    <color rgba="0 1 1 0.4"/>
  </material>
  <material name="orange_transparent">
    <color rgba="1 0.5 0 0.4"/>
  </material>
  <material name="gray_transparent">
    <color rgba="0.6 0.6 0.6 0.4"/>
  </material>
  <material name="blue_transparent">
    <color rgba="0 0.8 1 0.4"/>
  </material>
  <link name="workcell_frame"/>
  <!-- property list -->
  <!-- instantiating arm and gripper -->
  <link name="ur5_arm_base_link">
    <visual>
      <geometry>
        <mesh filename="package://ur5_description/meshes/Base.dae"/>
      </geometry>
      <origin rpy="0.0 0.0 2.3561944875" xyz="0.0 0.0 0.003"/>
    </visual>
    <inertial>
      <mass value="4.0"/>
      <inertia ixx="1.0" ixy="0.0" ixz="0.0" iyy="1.0" iyz="0.0" izz="1.0"/>
    </inertial>
  </link>
  <joint name="ur5_arm_shoulder_pan_joint" type="revolute">
    <parent link="ur5_arm_base_link"/>
    <child link="ur5_arm_shoulder_link"/>
    <origin rpy="0.0 0.0 0.0" xyz="0.0 0.0 0.089159"/>
    <axis xyz="0.0 0.0 1.0"/>
    <limit effort="10.0" lower="-6.2831853" upper="6.2831853" velocity="3.14159265"/>
    <dynamics damping="10" friction="0.1"/>
  </joint>
  <link name="ur5_arm_shoulder_link">
    <visual>
      <geometry>
        <mesh filename="package://ur5_description/meshes/Shoulder.dae"/>
      </geometry>
    </visual>
    <collision>
      <geometry>
        <cylinder length="0.16" radius="0.06"/>
      </geometry>
      <origin rpy="0.0 0.0 0.0" xyz="0.0 0.0 -0.009159"/>
    </collision>
    <inertial>
      <mass value="3.7"/>
      <inertia ixx="1.0" ixy="0.0" ixz="0.0" iyy="1.0" iyz="0.0" izz="1.0"/>
      <origin rpy="0.0 0.0 0.0" xyz="0.0 0.00193 -0.02561"/>
    </inertial>
  </link>
  <joint name="ur5_arm_shoulder_lift_joint" type="revolute">
    <parent link="ur5_arm_shoulder_link"/>
    <child link="ur5_arm_upper_arm_link"/>
    <origin rpy="0.0 1.570796325 0.0" xyz="0.0 0.13585 0.0"/>
    <axis xyz="0.0 1.0 0.0"/>
    <limit effort="10.0" lower="-6.2831853" upper="6.2831853" velocity="3.14159265"/>
    <dynamics damping="10" friction="0.1"/>
  </joint>
  <link name="ur5_arm_upper_arm_link">
    <visual>
      <geometry>
        <mesh filename="package://ur5_description/meshes/UpperArm.dae"/>
      </geometry>
      <origin rpy="0.0 0.0 0.0" xyz="0.0 0.0 0.0"/>
    </visual>
    <collision>
      <geometry>
        <cylinder length="0.425" radius="0.054"/>
      </geometry>
      <origin rpy="0.0 0.0 0.0" xyz="0.0 0.0 0.2125"/>
    </collision>
    <inertial>
      <mass value="8.393"/>
      <inertia ixx="1.0" ixy="0.0" ixz="0.0" iyy="1.0" iyz="0.0" izz="1.0"/>
      <origin rpy="0.0 0.0 0.0" xyz="0.0 -0.024201 0.2125"/>
    </inertial>
  </link>
  <joint name="ur5_arm_elbow_joint" type="revolute">
    <parent link="ur5_arm_upper_arm_link"/>
    <child link="ur5_arm_forearm_link"/>
    <origin rpy="0.0 0.0 0.0" xyz="0.0 -0.1197 0.425"/>
    <axis xyz="0.0 1.0 0.0"/>
    <limit effort="10.0" lower="-6.2831853" upper="6.2831853" velocity="3.14159265"/>
    <dynamics damping="10" friction="0.1"/>
  </joint>
  <link name="ur5_arm_forearm_link">
    <visual>
      <geometry>
        <mesh filename="package://ur5_description/meshes/Forearm.dae"/>
      </geometry>
    </visual>
    <collision>
      <geometry>
        <cylinder length="0.39225" radius="0.04"/>
      </geometry>
      <origin rpy="0.0 0.0 0.0" xyz="0.0 0.0 0.196125"/>
    </collision>
    <inertial>
      <mass value="2.275"/>
      <origin rpy="0.0 0.0 0.0" xyz="0.0 0.0265 0.11993"/>
      <inertia ixx="1.0" ixy="0.0" ixz="0.0" iyy="1.0" iyz="0.0" izz="1.0"/>
    </inertial>
  </link>
  <joint name="ur5_arm_wrist_1_joint" type="revolute">
    <parent link="ur5_arm_forearm_link"/>
    <child link="ur5_arm_wrist_1_link"/>
    <origin rpy="0.0 1.570796325 0.0" xyz="0.0 0.0 0.39225"/>
    <axis xyz="0.0 1.0 0.0"/>
    <limit effort="10.0" lower="-6.2831853" upper="6.2831853" velocity="3.14159265"/>
    <dynamics damping="10" friction="0.1"/>
  </joint>
  <link name="ur5_arm_wrist_1_link">
    <visual>
      <geometry>
        <mesh filename="package://ur5_description/meshes/Wrist1.dae"/>
      </geometry>
      <origin rpy="0.0 1.570796325 0.0" xyz="0.0 0.093 0.0"/>
    </visual>
    <collision>
      <geometry>
        <cylinder length="0.1488" radius="0.045"/>
      </geometry>
      <origin rpy="-1.570796325 0.0 0.0" xyz="0.0 0.02325 0.0"/>
    </collision>
    <inertial>
      <mass value="1.219"/>
      <origin rpy="0.0 0.0 0.0" xyz="0.0 0.110949 0.01634"/>
      <inertia ixx="1.0" ixy="0.0" ixz="0.0" iyy="1.0" iyz="0.0" izz="1.0"/>
    </inertial>
  </link>
  <joint name="ur5_arm_wrist_2_joint" type="revolute">
    <parent link="ur5_arm_wrist_1_link"/>
    <child link="ur5_arm_wrist_2_link"/>
    <origin rpy="0.0 0.0 0.0" xyz="0.0 0.093 0.0"/>
    <axis xyz="0.0 0.0 1.0"/>
    <limit effort="10.0" lower="-6.2831853" upper="6.2831853" velocity="3.14159265"/>
    <dynamics damping="10" friction="0.1"/>
  </joint>
  <link name="ur5_arm_wrist_2_link">
    <visual>
      <geometry>
        <mesh filename="package://ur5_description/meshes/Wrist2.dae"/>
      </geometry>
      <origin rpy="0.0 0.0 0.0" xyz="0.0 0.0 0.09465"/>
    </visual>
    <collision>
      <geometry>
        <cylinder length="0.15144" radius="0.045"/>
      </geometry>
      <origin rpy="0.0 0.0 0.0" xyz="0.0 0.0 0.0236625"/>
    </collision>
    <inertial>
      <mass value="1.219"/>
      <origin rpy="0.0 0.0 0.0" xyz="0.0 0.0018 0.11099"/>
      <inertia ixx="1.0" ixy="0.0" ixz="0.0" iyy="1.0" iyz="0.0" izz="1.0"/>
    </inertial>
  </link>
  <joint name="ur5_arm_wrist_3_joint" type="revolute">
    <parent link="ur5_arm_wrist_2_link"/>
    <child link="ur5_arm_wrist_3_link"/>
    <origin rpy="0.0 0.0 0.0" xyz="0.0 0.0 0.09465"/>
    <axis xyz="0.0 1.0 0.0"/>
    <limit effort="10.0" lower="-6.2831853" upper="6.2831853" velocity="3.14159265"/>
    <dynamics damping="10" friction="0.1"/>
  </joint>
  <link name="ur5_arm_wrist_3_link">
    <visual>
      <geometry>
        <mesh filename="package://ur5_description/meshes/Wrist3.dae"/>
      </geometry>
    </visual>
    <collision>
      <geometry>
        <cylinder length="0.135795" radius="0.045"/>
      </geometry>
      <origin rpy="-1.570796325 0.0 0.0" xyz="0.0 0.012345 0.0"/>
    </collision>
    <inertial>
      <mass value="0.1879"/>
      <origin rpy="0.0 0.0 0.0" xyz="0.0 0.001159 0.0"/>
      <inertia ixx="1.0" ixy="0.0" ixz="0.0" iyy="1.0" iyz="0.0" izz="1.0"/>
    </inertial>
  </link>
  <joint name="ur5_arm_ee_fixed_joint" type="fixed">
    <parent link="ur5_arm_wrist_3_link"/>
    <child link="ur5_arm_ee_link"/>
    <origin rpy="0.0 0.0 1.570796325" xyz="0.0 0.0823 0.0"/>
  </joint>
  <link name="ur5_arm_ee_link"/>
  <transmission name="shoulder_pan_trans" type="pr2_mechanism_model/SimpleTransmission">
    <actuator name="shoulder_pan_motor"/>
    <joint name="ur5_arm_shoulder_pan_joint"/>
    <mechanicalReduction>1</mechanicalReduction>
  </transmission>
  <transmission name="shoulder_lift_trans" type="pr2_mechanism_model/SimpleTransmission">
    <actuator name="shoulder_lift_motor"/>
    <joint name="ur5_arm_shoulder_lift_joint"/>
    <mechanicalReduction>1</mechanicalReduction>
  </transmission>
  <transmission name="elbow_trans" type="pr2_mechanism_model/SimpleTransmission">
    <actuator name="elbow_motor"/>
    <joint name="ur5_arm_elbow_joint"/>
    <mechanicalReduction>1</mechanicalReduction>
  </transmission>
  <transmission name="wrist_1_trans" type="pr2_mechanism_model/SimpleTransmission">
    <actuator name="wrist_1_motor"/>
    <joint name="ur5_arm_wrist_1_joint"/>
    <mechanicalReduction>1</mechanicalReduction>
  </transmission>
  <transmission name="wrist_2_trans" type="pr2_mechanism_model/SimpleTransmission">
    <actuator name="wrist_2_motor"/>
    <joint name="ur5_arm_wrist_2_joint"/>
    <mechanicalReduction>1</mechanicalReduction>
  </transmission>
  <transmission name="wrist_3_trans" type="pr2_mechanism_model/SimpleTransmission">
    <actuator name="wrist_3_motor"/>
    <joint name="ur5_arm_wrist_3_joint"/>
    <mechanicalReduction>1</mechanicalReduction>
  </transmission>
  <gazebo reference="universal_robot">
    <material>Gazebo/Blue</material>
  </gazebo>
  <link name="ur5_arm_gripper_frame"/>
  <link name="ur5_arm_gripper_body">
    <visual>
      <!--origin xyz="0 0.036 -0.0473" rpy="0 0 0"/-->
      <geometry>
        <box size="0.044 0.088 0.0946"/>
      </geometry>
      <material name="another_blue1">
        <color rgba="0.40 0.40 0.80 1"/>
      </material>
    </visual>
    <collision>
      <geometry>
        <box size="0.044 0.088 0.0946"/>
      </geometry>
      <material name="another_blue2">
        <color rgba="0.38 0.54 0.83 1"/>
      </material>
    </collision>
  </link>
  <link name="ur5_arm_tcp_frame"/>
  <joint name="ur5_arm_gripper_to_palm" type="fixed">
    <parent link="ur5_arm_gripper_frame"/>
    <child link="ur5_arm_gripper_body"/>
    <origin rpy="0 0 0" xyz="0 0 0.0473"/>
  </joint>
  <joint name="ur5_arm_gripper_to_tcp" type="fixed">
    <parent link="ur5_arm_gripper_frame"/>
    <child link="ur5_arm_tcp_frame"/>
    <origin rpy="0 0 0" xyz="0.022 0 0.0946"/>
  </joint>
  <!-- instantiating workcell definitions -->
  <link name="table_base2">
    <visual>
      <origin rpy="0 0 0" xyz="0 0 -0.5"/>
      <geometry>
        <box size="1.3875 2.22 1"/>
      </geometry>
      <material name="orange_transparent"/>
    </visual>
    <collision>
      <origin rpy="0 0 0" xyz="0 0 -0.5"/>
      <geometry>
        <box size="1.3875 2.22 1"/>
      </geometry>
      <material name="blue_transparent"/>
    </collision>
  </link>
  <joint name="workcell_to_table_base2" type="fixed">
    <parent link="workcell_frame"/>
    <child link="table_base2"/>
    <origin rpy="0 0 0" xyz="-0.69375 0 0"/>
  </joint>
  <link name="front_wall2">
    <visual>
      <geometry>
        <box size="0.1 2.22 1"/>
      </geometry>
      <material name="gray_transparent"/>
    </visual>
    <collision>
      <geometry>
        <box size="0.1 2.22 1"/>
      </geometry>
      <material name="blue_transparent"/>
    </collision>
  </link>
  <joint name="workcell_frame_to_front_wall2" type="fixed">
    <parent link="workcell_frame"/>
    <child link="front_wall2"/>
    <origin rpy="0 0 0" xyz="-1.3375 0 0.5"/>
  </joint>
  <link name="back_wall2">
    <visual>
      <geometry>
        <box size="0.04 2.0 1"/>
      </geometry>
      <material name="gray_transparent"/>
    </visual>
    <collision>
      <geometry>
        <box size="0.04 2.0 1"/>
      </geometry>
      <material name="blue_transparent"/>
    </collision>
  </link>
  <joint name="workcell_frame_to_back_wall2" type="fixed">
    <parent link="workcell_frame"/>
    <child link="back_wall2"/>
    <origin rpy="0 0 0" xyz="-0.02 0 0.5"/>
  </joint>
  <link name="left_wall2">
    <visual>
      <geometry>
        <box size="1.384 0.284 1"/>
      </geometry>
      <material name="gray_transparent"/>
    </visual>
    <collision>
      <geometry>
        <box size="1.384 0.284 1"/>
      </geometry>
      <material name="blue_transparent"/>
    </collision>
  </link>
  <joint name="workcell_frame_to_left_wall2" type="fixed">
    <parent link="workcell_frame"/>
    <child link="left_wall2"/>
    <origin rpy="0 0 0" xyz="-0.601 0.968 0.5"/>
  </joint>
  <link name="right_wall2">
    <visual>
      <geometry>
        <box size="1.384 0.284 1"/>
      </geometry>
      <material name="gray_transparent"/>
    </visual>
    <collision>
      <geometry>
        <box size="1.384 0.284 1"/>
      </geometry>
      <material name="blue_transparent"/>
    </collision>
  </link>
  <joint name="workcell_frame_to_right_wall2" type="fixed">
    <parent link="workcell_frame"/>
    <child link="right_wall2"/>
    <origin rpy="0 0 0" xyz="-0.601 -0.968 0.5"/>
  </joint>
  <link name="cover_part1">
    <visual>
      <geometry>
        <box size="0.229 0.508 0.14"/>
      </geometry>
      <material name="gray_transparent"/>
    </visual>
    <collision>
      <geometry>
        <box size="0.229 0.508 0.14"/>
      </geometry>
      <material name="blue_transparent"/>
    </collision>
  </link>
  <joint name="workcell_frame_to_cover_part1" type="fixed">
    <parent link="workcell_frame"/>
    <child link="cover_part1"/>
    <origin rpy="0 0 0" xyz="-0.042 -0.081 0.07"/>
  </joint>
  <link name="cover_part2">
    <visual>
      <geometry>
        <box size="0.121 0.26 0.14"/>
      </geometry>
      <material name="gray_transparent"/>
    </visual>
    <collision>
      <geometry>
        <box size="0.121 0.26 0.14"/>
      </geometry>
      <material name="blue_transparent"/>
    </collision>
  </link>
  <joint name="workcell_frame_to_cover_part2" type="fixed">
    <parent link="workcell_frame"/>
    <child link="cover_part2"/>
    <origin rpy="0 0 0" xyz="-0.012 -0.465 0.07"/>
  </joint>
  <!-- end of workcell definitions -->
  <!-- instantiating sensor definitions -->
  <material name="ur5_arm_color_b">
    <color rgba="0 0.8 1 0.4"/>
  </material>
  <material name="ur5_arm_color_a">
    <color rgba="0.8 0.2 1 0.2"/>
  </material>
  <material name="ur5_arm_silver">
    <color rgba="0.6 0.6 0.6 1"/>
  </material>
  <link name="ur5_arm_kinect">
    <collision>
      <material name="ur5_arm_color_a"/>
      <geometry>
        <box size="0.36 0.28 0.22"/>
      </geometry>
    </collision>
  </link>
  <link name="ur5_arm_kinect_keepout">
    <collision>
      <material name="ur5_arm_color_b"/>
      <geometry>
        <box size="0.2 0.32 0.48"/>
      </geometry>
    </collision>
  </link>
  <link name="ur5_arm_kinect_frame">
    <visual>
      <origin rpy="0 0 0" xyz="0 0 0"/>
      <geometry>
        <box size="0.064 0.28 0.04"/>
      </geometry>
      <material name="ur5_arm_silver"/>
    </visual>
    <collision>
      <origin rpy="0 0 0" xyz="0 0 0"/>
      <geometry>
        <box size="0.064 0.28 0.04"/>
      </geometry>
    </collision>
  </link>
  <link name="ur5_arm_kinect_ir_link">
    <visual>
      <origin rpy="0 0 0" xyz="0 0 0"/>
      <geometry>
        <sphere radius="0.0005"/>
      </geometry>
    </visual>
  </link>
  <link name="ur5_arm_kinect_rgb_link">
    <visual>
      <origin rpy="0 0 0" xyz="0 0 0"/>
      <geometry>
        <sphere radius="0.0005"/>
      </geometry>
    </visual>
  </link>
  <link name="ur5_arm_kinect_ir_optical_frame"/>
  <link name="ur5_arm_kinect_rgb_optical_frame"/>
  <joint name="ur5_arm_kinect_frame_joint" type="fixed">
    <parent link="ur5_arm_kinect"/>
    <child link="ur5_arm_kinect_frame"/>
    <origin rpy="0 0 0" xyz="0 0 0"/>
  </joint>
  <joint name="ur5_arm_kinect_ir_joint" type="fixed">
    <parent link="ur5_arm_kinect_frame"/>
    <child link="ur5_arm_kinect_ir_link"/>
    <origin rpy="0 0 0" xyz="0 0 0"/>
  </joint>
  <joint name="ur5_arm_kinect_ir_optical_frame_joint" type="fixed">
    <parent link="ur5_arm_kinect_ir_link"/>
    <child link="ur5_arm_kinect_ir_optical_frame"/>
    <origin rpy="-1.57 0 -1.57" xyz="0 0 0"/>
  </joint>
  <joint name="ur5_arm_kinect_rgb_joint" type="fixed">
    <parent link="ur5_arm_kinect_ir_link"/>
    <child link="ur5_arm_kinect_rgb_link"/>
    <origin rpy="0 0 0" xyz="0 -0.03 0"/>
  </joint>
  <joint name="ur5_arm_kinect_rgb_optical_frame_joint" type="fixed">
    <parent link="ur5_arm_kinect_rgb_link"/>
    <child link="ur5_arm_kinect_rgb_optical_frame"/>
    <origin rpy="-1.57 0 -1.57" xyz="0 0 0"/>
  </joint>
  <joint name="ur5_arm_workcell_frame_to_kinect" type="fixed">
    <parent link="workcell_frame"/>
    <child link="ur5_arm_kinect"/>
    <origin rpy="0 0.5235 0" xyz="-1.2 0 0.4"/>
  </joint>
  <joint name="ur5_arm_workcell_frame_to_kinect_keepout" type="fixed">
    <parent link="workcell_frame"/>
    <child link="ur5_arm_kinect_keepout"/>
    <origin rpy="0 0 0" xyz="-1.2 0 0.24"/>
  </joint>
  <!-- end of sensor definitions -->
  <!-- arm-workcell link definitions -->
  <link name="ur5_stand">
    <visual>
      <geometry>
        <cylinder length="0.20" radius="0.0735"/>
      </geometry>
      <material name="orange_transparent"/>
    </visual>
    <collision>
      <geometry>
        <cylinder length="0.20" radius="0.0735"/>
      </geometry>
      <material name="blue_transparent"/>
    </collision>
  </link>
  <joint name="workcell_to_stand" type="fixed">
    <parent link="workcell_frame"/>
    <child link="ur5_stand"/>
    <origin xyz="-0.238 0 0.10"/>
  </joint>
  <!-- end of arm-workcell link definitions -->
  <!-- arm-workcell joint definitions -->
  <joint name="ur5_to_stand" type="fixed">
    <parent link="ur5_stand"/>
    <child link="ur5_arm_base_link"/>
    <origin rpy="0 0 -3.14" xyz="0 0 0.10"/>
  </joint>
  <!-- end of arm workcell joint definitions-->
  <!-- arm-gripper coupling joint definitions -->
  <joint name="ur5_to_gripper" type="fixed">
    <parent link="ur5_arm_ee_link"/>
    <child link="ur5_arm_gripper_frame"/>
    <origin rpy="0 1.57 0" xyz="0 0 0"/>
  </joint>
  <!-- end of arm-gripper coupling joint definitions -->
</robot>

