<?xml version="1.0" ?>
<!-- =================================================================================== -->
<!-- |    This document was autogenerated by xacro from longhorn.xacro                 | -->
<!-- |    EDITING THIS FILE BY HAND IS NOT RECOMMENDED                                 | -->
<!-- =================================================================================== -->
<robot name="longhorn" xmlns:xacro="http://ros.org/wiki/xacro">
  <link name="base_link">
    <visual>
      <geometry>
        <mesh filename="package://motoman_config/meshes/sia20d/visual/MOTOMAN_BASE.stl"/>
      </geometry>
      <material name="blue">
        <color rgba="0 0 1 1"/>
      </material>
    </visual>
    <collision>
      <geometry>
        <mesh filename="package://motoman_config/meshes/sia20d/collision/MOTOMAN_BASE.stl"/>
      </geometry>
      <material name="yellow">
        <color rgba="0 1 1 1"/>
      </material>
    </collision>
  </link>
  <link name="link_s">
    <visual>
      <origin rpy="0 0 3.1416" xyz="0 0 0"/>
      <geometry>
        <mesh filename="package://motoman_config/meshes/sia20d/visual/MOTOMAN_AXIS_S.stl"/>
      </geometry>
      <material name="silver">
        <color rgba="0.8 0.8 0.8 1"/>
      </material>
    </visual>
    <collision>
      <origin rpy="0 0 3.1416" xyz="0 0 0"/>
      <geometry>
        <mesh filename="package://motoman_config/meshes/sia20d/collision/MOTOMAN_AXIS_S.stl"/>
      </geometry>
      <material name="yellow"/>
    </collision>
  </link>
  <link name="link_l">
    <visual>
      <origin rpy="1.57 3.1416 3.1416" xyz="0 0 0"/>
      <geometry>
        <mesh filename="package://motoman_config/meshes/sia20d/visual/MOTOMAN_AXIS_L.stl"/>
      </geometry>
      <material name="blue"/>
    </visual>
    <collision>
      <origin rpy="1.57 3.1416 3.1416" xyz="0 0 0"/>
      <geometry>
        <mesh filename="package://motoman_config/meshes/sia20d/collision/MOTOMAN_AXIS_L.stl"/>
      </geometry>
      <material name="yellow"/>
    </collision>
  </link>
  <link name="link_e">
    <visual>
      <origin rpy="0 0 0" xyz="0 0 0"/>
      <geometry>
        <mesh filename="package://motoman_config/meshes/sia20d/visual/MOTOMAN_AXIS_E.stl"/>
      </geometry>
      <material name="silver"/>
    </visual>
    <collision>
      <origin rpy="0 0 0" xyz="0 0 0"/>
      <geometry>
        <mesh filename="package://motoman_config/meshes/sia20d/collision/MOTOMAN_AXIS_E.stl"/>
      </geometry>
      <material name="yellow"/>
    </collision>
  </link>
  <link name="link_u">
    <visual>
      <origin rpy="1.57 -3.1415 3.1416" xyz="0 0 0"/>
      <geometry>
        <mesh filename="package://motoman_config/meshes/sia20d/visual/MOTOMAN_AXIS_U.stl"/>
      </geometry>
      <material name="blue"/>
    </visual>
    <collision>
      <origin rpy="1.57 -3.1415 3.1416" xyz="0 0 0"/>
      <geometry>
        <mesh filename="package://motoman_config/meshes/sia20d/collision/MOTOMAN_AXIS_U.stl"/>
      </geometry>
      <material name="yellow"/>
    </collision>
  </link>
  <link name="link_r">
    <visual>
      <origin rpy="0 0 0" xyz="0 0 0"/>
      <geometry>
        <mesh filename="package://motoman_config/meshes/sia20d/visual/MOTOMAN_AXIS_R.stl"/>
      </geometry>
      <material name="silver"/>
    </visual>
    <collision>
      <origin rpy="0 0 0" xyz="0 0 0"/>
      <geometry>
        <mesh filename="package://motoman_config/meshes/sia20d/collision/MOTOMAN_AXIS_R.stl"/>
      </geometry>
      <material name="yellow"/>
    </collision>
  </link>
  <link name="link_b">
    <visual>
      <origin rpy="-1.57 0 0" xyz="0 0 0"/>
      <geometry>
        <mesh filename="package://motoman_config/meshes/sia20d/visual/MOTOMAN_AXIS_B.stl"/>
      </geometry>
      <material name="blue"/>
    </visual>
    <collision>
      <origin rpy="-1.57 0 0" xyz="0 0 0"/>
      <geometry>
        <mesh filename="package://motoman_config/meshes/sia20d/collision/MOTOMAN_AXIS_B.stl"/>
      </geometry>
      <material name="yellow"/>
    </collision>
  </link>
  <link name="link_t">
    <visual>
      <geometry>
        <mesh filename="package://motoman_config/meshes/sia20d/visual/MOTOMAN_AXIS_T.stl"/>
      </geometry>
      <material name="silver"/>
    </visual>
    <collision>
      <geometry>
        <mesh filename="package://motoman_config/meshes/sia20d/collision/MOTOMAN_AXIS_T.stl"/>
      </geometry>
      <material name="yellow"/>
    </collision>
  </link>
  <joint name="joint_s" type="revolute">
    <parent link="base_link"/>
    <child link="link_s"/>
    <origin rpy="0 0 0" xyz="0 0 0.41"/>
    <axis xyz="0 0 1"/>
    <limit effort="100" lower="-3.1416" upper="3.1416" velocity="2.26"/>
  </joint>
  <joint name="joint_l" type="revolute">
    <parent link="link_s"/>
    <child link="link_l"/>
    <origin rpy="0 0 0" xyz="0 0 0"/>
    <axis xyz="0 1 0"/>
    <limit effort="100" lower="-1.91" upper="1.91" velocity="2.26"/>
  </joint>
  <joint name="joint_e" type="revolute">
    <parent link="link_l"/>
    <child link="link_e"/>
    <origin rpy="0 0 0" xyz="0 0 0.49"/>
    <axis xyz="0 0 1"/>
    <limit effort="100" lower="-2.96" upper="2.96" velocity="2.96"/>
  </joint>
  <joint name="joint_u" type="revolute">
    <parent link="link_e"/>
    <child link="link_u"/>
    <origin rpy="0 0 0" xyz="0 0 0"/>
    <axis xyz="0 -1 0"/>
    <limit effort="100" lower="-2.26" upper="2.26" velocity="2.96"/>
  </joint>
  <joint name="joint_r" type="revolute">
    <parent link="link_u"/>
    <child link="link_r"/>
    <origin rpy="0 0 0" xyz="0 0 0.420"/>
    <axis xyz="0 0 -1"/>
    <limit effort="100" lower="-3.1416" upper="3.1416" velocity="3.48"/>
  </joint>
  <joint name="joint_b" type="revolute">
    <parent link="link_r"/>
    <child link="link_b"/>
    <origin rpy="0 0 0" xyz="0 0 0"/>
    <axis xyz="0 -1 0"/>
    <limit effort="100" lower="-1.91" upper="1.91" velocity="3.48"/>
  </joint>
  <joint name="joint_t" type="revolute">
    <parent link="link_b"/>
    <child link="link_t"/>
    <origin rpy="0 0 0" xyz="0 0 0.18"/>
    <axis xyz="0 0 -1"/>
    <limit effort="100" lower="-3.1416" upper="3.1416" velocity="6.97"/>
  </joint>
  <link name="palm">
    <visual>
      <geometry>
        <mesh filename="package://robotiq/meshes/s-model/visual/GRIPPER_OPEN_PALM.stl"/>
      </geometry>
      <material name="green">
        <color rgba="0 1 0 1"/>
      </material>
    </visual>
    <collision>
      <geometry>
        <mesh filename="package://robotiq/meshes/s-model/collision/GRIPPER_OPEN_PALM.stl"/>
      </geometry>
      <material name="yellow">
        <color rgba="0 1 1 1"/>
      </material>
    </collision>
  </link>
  <link name="finger_1">
    <visual>
      <geometry>
        <mesh filename="package://robotiq/meshes/s-model/visual/GRIPPER_OPEN_FINGER_1.stl"/>
      </geometry>
      <material name="green"/>
    </visual>
    <collision>
      <geometry>
        <mesh filename="package://robotiq/meshes/s-model/collision/GRIPPER_OPEN_FINGER_1.stl"/>
      </geometry>
      <material name="yellow"/>
    </collision>
  </link>
  <link name="finger_2">
    <visual>
      <geometry>
        <mesh filename="package://robotiq/meshes/s-model/visual/GRIPPER_OPEN_FINGER_2.stl"/>
      </geometry>
      <material name="green"/>
    </visual>
    <collision>
      <geometry>
        <mesh filename="package://robotiq/meshes/s-model/collision/GRIPPER_OPEN_FINGER_2.stl"/>
      </geometry>
      <material name="yellow"/>
    </collision>
  </link>
  <link name="finger_3">
    <visual>
      <geometry>
        <mesh filename="package://robotiq/meshes/s-model/visual/GRIPPER_OPEN_FINGER_3.stl"/>
      </geometry>
      <material name="green"/>
    </visual>
    <collision>
      <geometry>
        <mesh filename="package://robotiq/meshes/s-model/collision/GRIPPER_OPEN_FINGER_3.stl"/>
      </geometry>
      <material name="yellow"/>
    </collision>
  </link>
  <joint name="joint_1" type="fixed">
    <parent link="palm"/>
    <child link="finger_1"/>
    <origin rpy="0 0 0" xyz="0 0 0"/>
  </joint>
  <joint name="joint_2" type="fixed">
    <parent link="palm"/>
    <child link="finger_2"/>
    <origin rpy="0 0 0" xyz="0 0 0"/>
  </joint>
  <joint name="joint_3" type="fixed">
    <parent link="palm"/>
    <child link="finger_3"/>
    <origin rpy="0 0 0" xyz="0 0 0"/>
  </joint>
  <!-- link list -->
  <link name="coupler">
    <visual>
      <geometry>
        <mesh filename="package://longhorn/meshes/coupler/visual/COUPLER.stl"/>
      </geometry>
      <material name="orange">
        <color rgba="1 0.5 0 1"/>
      </material>
    </visual>
    <collision>
      <geometry>
        <mesh filename="package://longhorn/meshes/coupler/collision/COUPLER.stl"/>
      </geometry>
      <material name="yellow">
        <color rgba="0 1 1 1"/>
      </material>
    </collision>
  </link>
  <!-- end link list -->
  <!-- joint list -->
  <joint name="tool-coupler" type="fixed">
    <parent link="link_t"/>
    <child link="coupler"/>
    <origin rpy="1.570 0 0" xyz="0 0 0"/>
  </joint>
  <joint name="coupler-hand" type="fixed">
    <parent link="coupler"/>
    <child link="palm"/>
    <origin rpy="-1.570 -2.356 0" xyz="0 0.240 0"/>
  </joint>
  <!-- end of joint list -->
  <!-- environment list -->
  <link name="table">
    <visual>
      <geometry>
        <box size="1.83 2.44 0.25"/>
      </geometry>
      <material name="">
        <color rgba="1 0 1 1"/>
      </material>
    </visual>
    <collision>
      <geometry>
        <box size="1.83 2.44 0.25"/>
      </geometry>
      <material name="">
        <color rgba="1 0 1 1"/>
      </material>
    </collision>
  </link>
  <link name="table_keepout_1">
    <collision>
      <geometry>
        <box size="2.08 0.25 2"/>
      </geometry>
      <material name="">
        <color rgba="1 0.2 1 0.1"/>
      </material>
    </collision>
  </link>
  <link name="table_keepout_2">
    <collision>
      <geometry>
        <box size="0.25 2.69 2"/>
      </geometry>
      <material name="">
        <color rgba="1 0.2 1 0.1"/>
      </material>
    </collision>
  </link>
  <link name="abb_keepout">
    <collision>
      <geometry>
        <box size="0.915 1.524 2"/>
      </geometry>
      <material name="">
        <color rgba="1 0.2 1 0.1"/>
      </material>
    </collision>
  </link>
  <link name="power_supply">
    <visual>
      <geometry>
        <box size="0.400 0.250 0.115"/>
      </geometry>
      <material name="">
        <color rgba="1 0.2 1 0.1"/>
      </material>
    </visual>
    <collision>
      <geometry>
        <box size="0.400 0.250 0.115"/>
      </geometry>
      <material name="">
        <color rgba="1 0.2 1 0.1"/>
      </material>
    </collision>
  </link>
  <link name="kinect_keepout">
    <collision>
      <geometry>
        <box size="0.25 2.69 2"/>
      </geometry>
      <material name="">
        <color rgba="1 0.2 1 0.1"/>
      </material>
    </collision>
  </link>
  <link name="kinect">
    <collision>
      <geometry>
        <box size="0.36 0.28 0.22"/>
      </geometry>
      <material name="">
        <color rgba="1 0.8 1 0.1"/>
      </material>
    </collision>
  </link>
  <joint name="base-table" type="fixed">
    <parent link="base_link"/>
    <child link="table"/>
    <origin rpy="0 0 -0.785" xyz="1.19 0.22 -0.125"/>
  </joint>
  <joint name="base-kinect" type="fixed">
    <parent link="base_link"/>
    <child link="kinect"/>
    <origin rpy="0 0.5235 2.356" xyz="1.08 -0.72 0.82"/>
  </joint>
  <joint name="table-keepout_1" type="fixed">
    <parent link="table"/>
    <child link="table_keepout_1"/>
    <origin rpy="0 0 0" xyz="0 -1.34 1"/>
  </joint>
  <joint name="table-keepout_2" type="fixed">
    <parent link="table"/>
    <child link="table_keepout_2"/>
    <origin rpy="0 0 0" xyz="-1.025 0 1"/>
  </joint>
  <joint name="abb-keepout" type="fixed">
    <parent link="table"/>
    <child link="abb_keepout"/>
    <origin rpy="0 0 0" xyz="0.475 0.458 1.125"/>
  </joint>
  <joint name="base-power_supply" type="fixed">
    <parent link="base_link"/>
    <child link="power_supply"/>
    <origin rpy="0 0 0" xyz="0 -0.260 0.050"/>
  </joint>
  <joint name="table-kinect" type="fixed">
    <parent link="table"/>
    <child link="kinect_keepout"/>
    <origin rpy="0 0 0" xyz=".5 0 1"/>
  </joint>
  <!-- end environment list -->
  <!-- kinect -->
  <joint name="kinect_frame_joint" type="fixed">
    <parent link="kinect"/>
    <child link="kinect_frame"/>
    <origin rpy="0 0 0" xyz="0 0 0"/>
  </joint>
  <link name="kinect_frame">
    <visual>
      <origin rpy="0 0 0" xyz="0 0 0"/>
      <geometry>
        <box size="0.064 0.28 0.04"/>
      </geometry>
      <material name="silver"/>
    </visual>
    <collision>
      <origin rpy="0 0 0" xyz="0 0 0"/>
      <geometry>
        <box size="0.064 0.28 0.04"/>
      </geometry>
    </collision>
  </link>
  <joint name="kinect_ir_joint" type="fixed">
    <parent link="kinect_frame"/>
    <child link="kinect_ir_link"/>
    <origin rpy="0 0 0" xyz="0 0 0"/>
  </joint>
  <link name="kinect_ir_link">
    <visual>
      <origin rpy="0 0 0" xyz="0 0 0"/>
      <geometry>
        <sphere radius="0.0005"/>
      </geometry>
    </visual>
  </link>
  <joint name="kinect_ir_optical_frame_joint" type="fixed">
    <parent link="kinect_ir_link"/>
    <child link="kinect_ir_optical_frame"/>
    <origin rpy="-1.57 0 -1.57" xyz="0 0 0"/>
  </joint>
  <link name="kinect_ir_optical_frame"/>
  <joint name="kinect_rgb_joint" type="fixed">
    <parent link="kinect_ir_link"/>
    <child link="kinect_rgb_link"/>
    <origin rpy="0 0 0" xyz="0 -0.03 0"/>
  </joint>
  <link name="kinect_rgb_link">
    <visual>
      <origin rpy="0 0 0" xyz="0 0 0"/>
      <geometry>
        <sphere radius="0.0005"/>
      </geometry>
    </visual>
  </link>
  <joint name="kinect_rgb_optical_frame_joint" type="fixed">
    <parent link="kinect_rgb_link"/>
    <child link="kinect_rgb_optical_frame"/>
    <origin rpy="-1.57 0 -1.57" xyz="0 0 0"/>
  </joint>
  <link name="kinect_rgb_optical_frame"/>
  <!-- end kinect -->
</robot>

