<?xml version="1.0" ?>
<robot name="armadillo" xmlns:xacro="http://ros.org/wiki/xacro">
  <link name="base_link">
    <visual>
      <geometry>
        <mesh filename="package://motoman_config/meshes/sia10d/visual/MOTOMAN_BASE.stl"/>
      </geometry>
      <material name="blue">
        <color rgba="0 0 1 1"/>
      </material>
    </visual>
    <collision>
      <geometry>
        <mesh filename="package://motoman_config/meshes/sia10d/collision/MOTOMAN_BASE.stl"/>
      </geometry>
    </collision>
  </link>
  <link name="link_s">
    <visual>
      <geometry>
        <mesh filename="package://motoman_config/meshes/sia10d/visual/MOTOMAN_AXIS_S.stl"/>
      </geometry>
      <material name="silver">
        <color rgba="0.8 0.8 0.8 1"/>
      </material>
    </visual>
    <collision>
      <geometry>
        <mesh filename="package://motoman_config/meshes/sia10d/collision/MOTOMAN_AXIS_S.stl"/>
      </geometry>
    </collision>
  </link>
  <link name="link_l">
    <visual>
      <origin rpy="1.57 3.1416 0" xyz="0 0 0"/>
      <geometry>
        <mesh filename="package://motoman_config/meshes/sia10d/visual/MOTOMAN_AXIS_L.stl"/>
      </geometry>
      <material name="blue"/>
    </visual>
    <collision>
      <origin rpy="1.57 3.1416 0" xyz="0 0 0"/>
      <geometry>
        <mesh filename="package://motoman_config/meshes/sia10d/collision/MOTOMAN_AXIS_L.stl"/>
      </geometry>
    </collision>
  </link>
  <link name="link_e">
    <visual>
      <origin rpy="0 0 3.1415" xyz="0 0 0"/>
      <geometry>
        <mesh filename="package://motoman_config/meshes/sia10d/visual/MOTOMAN_AXIS_E.stl"/>
      </geometry>
      <material name="silver"/>
    </visual>
    <collision>
      <origin rpy="0 0 3.1415" xyz="0 0 0"/>
      <geometry>
        <mesh filename="package://motoman_config/meshes/sia10d/collision/MOTOMAN_AXIS_E.stl"/>
      </geometry>
    </collision>
  </link>
  <link name="link_u">
    <visual>
      <origin rpy="1.57 -3.1415 0" xyz="0 0 0"/>
      <geometry>
        <mesh filename="package://motoman_config/meshes/sia10d/visual/MOTOMAN_AXIS_U.stl"/>
      </geometry>
      <material name="blue"/>
    </visual>
    <collision>
      <origin rpy="1.57 -3.1415 0" xyz="0 0 0"/>
      <geometry>
        <mesh filename="package://motoman_config/meshes/sia10d/collision/MOTOMAN_AXIS_U.stl"/>
      </geometry>
    </collision>
  </link>
  <link name="link_r">
    <visual>
      <origin rpy="0 0 3.1516" xyz="0 0 0"/>
      <geometry>
        <mesh filename="package://motoman_config/meshes/sia10d/visual/MOTOMAN_AXIS_R.stl"/>
      </geometry>
      <material name="silver"/>
    </visual>
    <collision>
      <origin rpy="0 0 3.1516" xyz="0 0 0"/>
      <geometry>
        <mesh filename="package://motoman_config/meshes/sia10d/collision/MOTOMAN_AXIS_R.stl"/>
      </geometry>
    </collision>
  </link>
  <link name="link_b">
    <visual>
      <origin rpy="-1.57 0 3.1516" xyz="0 0 0"/>
      <geometry>
        <mesh filename="package://motoman_config/meshes/sia10d/visual/MOTOMAN_AXIS_B.stl"/>
      </geometry>
      <material name="blue"/>
    </visual>
    <collision>
      <origin rpy="-1.57 0 3.1516" xyz="0 0 0"/>
      <geometry>
        <mesh filename="package://motoman_config/meshes/sia10d/collision/MOTOMAN_AXIS_B.stl"/>
      </geometry>
    </collision>
  </link>
  <link name="link_t">
    <visual>
      <geometry>
        <mesh filename="package://motoman_config/meshes/sia10d/visual/MOTOMAN_AXIS_T.stl"/>
      </geometry>
      <material name="silver"/>
    </visual>
    <collision>
      <geometry>
        <mesh filename="package://motoman_config/meshes/sia10d/collision/MOTOMAN_AXIS_T.stl"/>
      </geometry>
    </collision>
  </link>
  <joint name="joint_s" type="revolute">
    <parent link="base_link"/>
    <child link="link_s"/>
    <origin rpy="0 0 0" xyz="0 0 0.36"/>
    <axis xyz="0 0 1"/>
    <limit effort="100" lower="-3.1416" upper="3.1416" velocity="2.96"/>
  </joint>
  <joint name="joint_l" type="revolute">
    <parent link="link_s"/>
    <child link="link_l"/>
    <origin rpy="0 0 0" xyz="0 0 0"/>
    <axis xyz="0 1 0"/>
    <limit effort="100" lower="-1.91" upper="1.91" velocity="2.96"/>
  </joint>
  <joint name="joint_e" type="revolute">
    <parent link="link_l"/>
    <child link="link_e"/>
    <origin rpy="0 0 0" xyz="0 0 0.36"/>
    <axis xyz="0 0 1"/>
    <limit effort="100" lower="-2.96" upper="2.96" velocity="2.96"/>
  </joint>
  <joint name="joint_u" type="revolute">
    <parent link="link_e"/>
    <child link="link_u"/>
    <origin rpy="0 0 0" xyz="0 0 0"/>
    <axis xyz="0 -1 0"/>
    <limit effort="100" lower="-2.35" upper="2.35" velocity="2.96"/>
  </joint>
  <joint name="joint_r" type="revolute">
    <parent link="link_u"/>
    <child link="link_r"/>
    <origin rpy="0 0 0" xyz="0 0 0.36"/>
    <axis xyz="0 0 -1"/>
    <limit effort="100" lower="-3.1416" upper="3.1416" velocity="3.48"/>
  </joint>
  <joint name="joint_b" type="revolute">
    <parent link="link_r"/>
    <child link="link_b"/>
    <origin rpy="-0 0 0" xyz="0 0 0"/>
    <axis xyz="0 -1 0"/>
    <limit effort="100" lower="-1.91" upper="1.91" velocity="3.48"/>
  </joint>
  <joint name="joint_t" type="revolute">
    <parent link="link_b"/>
    <child link="link_t"/>
    <origin rpy="0 -0 0.038751377539" xyz="0 0 0.155"/>
    <axis xyz="0 0 -1"/>
    <limit effort="100" lower="-3.1416" upper="3.1416" velocity="6.97"/>
  </joint>
  <link name="palm">
    <visual>
      <geometry>
        <mesh filename="package://robotiq/meshes/s-model/visual/GRIPPER_OPEN_PALM.stl"/>
      </geometry>
      <material name="green">
        <color rgba="0 1 0 1"/>
      </material>
    </visual>
    <collision>
      <geometry>
        <mesh filename="package://robotiq/meshes/s-model/collision/GRIPPER_OPEN_PALM.stl"/>
      </geometry>
    </collision>
  </link>
  <link name="finger_1">
    <visual>
      <geometry>
        <mesh filename="package://robotiq/meshes/s-model/visual/GRIPPER_OPEN_FINGER_1.stl"/>
      </geometry>
      <material name="green"/>
    </visual>
    <collision>
      <geometry>
        <mesh filename="package://robotiq/meshes/s-model/collision/GRIPPER_OPEN_FINGER_1.stl"/>
      </geometry>
    </collision>
  </link>
  <link name="finger_2">
    <visual>
      <geometry>
        <mesh filename="package://robotiq/meshes/s-model/visual/GRIPPER_OPEN_FINGER_2.stl"/>
      </geometry>
      <material name="green"/>
    </visual>
    <collision>
      <geometry>
        <mesh filename="package://robotiq/meshes/s-model/collision/GRIPPER_OPEN_FINGER_2.stl"/>
      </geometry>
    </collision>
  </link>
  <link name="finger_3">
    <visual>
      <geometry>
        <mesh filename="package://robotiq/meshes/s-model/visual/GRIPPER_OPEN_FINGER_3.stl"/>
      </geometry>
      <material name="green"/>
    </visual>
    <collision>
      <geometry>
        <mesh filename="package://robotiq/meshes/s-model/collision/GRIPPER_OPEN_FINGER_3.stl"/>
      </geometry>
    </collision>
  </link>
  <joint name="joint_1" type="fixed">
    <parent link="palm"/>
    <child link="finger_1"/>
    <origin rpy="0 0 0" xyz="0 0 0"/>
  </joint>
  <joint name="joint_2" type="fixed">
    <parent link="palm"/>
    <child link="finger_2"/>
    <origin rpy="0 0 0" xyz="0 0 0"/>
  </joint>
  <joint name="joint_3" type="fixed">
    <parent link="palm"/>
    <child link="finger_3"/>
    <origin rpy="0 0 0" xyz="0 0 0"/>
  </joint>
  <link name="coupler">
    <visual>
      <geometry>
        <mesh filename="package://armadillo/meshes/coupler/visual/COUPLER.stl"/>
      </geometry>
      <material name="orange">
        <color rgba="1 0.5 0 1"/>
      </material>
    </visual>
    <collision>
      <geometry>
        <mesh filename="package://armadillo/meshes/coupler/collision/COUPLER.stl"/>
      </geometry>
    </collision>
  </link>
  <joint name="tool-coupler" type="fixed">
    <parent link="link_t"/>
    <child link="coupler"/>
    <origin rpy="1.57 0 0" xyz="0 0 0"/>
  </joint>
  <joint name="coupler-hand" type="fixed">
    <parent link="coupler"/>
    <child link="palm"/>
    <origin rpy="-1.57 -0.478 0" xyz="0 0.24 0"/>
  </joint>
  <link name="pallet">
    <visual>
      <geometry>
        <box size="1.61 1.16 0.213"/>
      </geometry>
      <material name="">
        <color rgba="1 0 1 1"/>
      </material>
    </visual>
  </link>
  <link name="controller">
    <visual>
      <geometry>
        <box size="0.8 0.65 1"/>
      </geometry>
      <material name="">
        <color rgba="1 0.2 1 1"/>
      </material>
    </visual>
  </link>
  <link name="filter">
    <visual>
      <geometry>
        <box size="0.36 0.36 0.36"/>
      </geometry>
      <material name="">
        <color rgba="1 0.4 1 1"/>
      </material>
    </visual>
  </link>
  <link name="floor">
    <visual>
      <geometry>
        <box size="6 6 0.01"/>
      </geometry>
      <material name="">
        <color rgba="1 0.6 1 0.5"/>
      </material>
    </visual>
  </link>
  <link name="kinect"/>
  <link name="tables">
    <visual>
      <geometry>
        <box size="1.1 1.65 0.45"/>
      </geometry>
      <material name="">
        <color rgba="1 0.7 1 1"/>
      </material>
    </visual>
  </link>
  <joint name="base-pallet" type="fixed">
    <parent link="base_link"/>
    <child link="pallet"/>
    <origin rpy="0 0 0" xyz="-0.52 -0.34 -0.11"/>
  </joint>
  <joint name="base-controller" type="fixed">
    <parent link="base_link"/>
    <child link="controller"/>
    <origin rpy="0 0 0" xyz="-0.75 -0.5 0.5"/>
  </joint>
  <joint name="base-filter" type="fixed">
    <parent link="base_link"/>
    <child link="filter"/>
    <origin rpy="0 0 0" xyz="-0.17 -0.5 0.63"/>
  </joint>
  <joint name="pallet-floor" type="fixed">
    <parent link="pallet"/>
    <child link="floor"/>
    <origin rpy="0 0 0" xyz="0 0 -0.11"/>
  </joint>
  <joint name="filter-kinect" type="fixed">
    <parent link="filter"/>
    <child link="kinect"/>
    <origin rpy="0 0 0" xyz="0.18 0 0.29"/>
  </joint>
  <joint name="base-tables" type="fixed">
    <parent link="base_link"/>
    <child link="tables"/>
    <origin rpy="0 0 0" xyz="0.84 0 0"/>
  </joint>
  <joint name="kinect_frame_joint" type="fixed">
    <parent link="kinect"/>
    <child link="kinect_frame"/>
    <origin rpy="0.017759135222 0.411139298319 0.548799750991" xyz="0.0423756377 -0.021265677959 0.033542912151"/>
  </joint>
  <link name="kinect_frame">
    <visual>
      <origin rpy="0 0 0" xyz="0 0 0"/>
      <geometry>
        <box size="0.064 0.28 0.04"/>
      </geometry>
      <material name="silver"/>
    </visual>
    <collision>
      <origin rpy="0 0 0" xyz="0 0 0"/>
      <geometry>
        <box size="0.064 0.28 0.04"/>
      </geometry>
    </collision>
  </link>
  <joint name="kinect_ir_joint" type="fixed">
    <parent link="kinect_frame"/>
    <child link="kinect_ir_link"/>
    <origin rpy="0 0 0" xyz="0 0 0"/>
  </joint>
  <link name="kinect_ir_link">
    <visual>
      <origin rpy="0 0 0" xyz="0 0 0"/>
      <geometry>
        <sphere radius="0.0005"/>
      </geometry>
    </visual>
  </link>
  <joint name="kinect_ir_optical_frame_joint" type="fixed">
    <parent link="kinect_ir_link"/>
    <child link="kinect_ir_optical_frame"/>
    <origin rpy="-1.57 0 -1.57" xyz="0 0 0"/>
  </joint>
  <link name="kinect_ir_optical_frame"/>
  <joint name="kinect_rgb_joint" type="fixed">
    <parent link="kinect_ir_link"/>
    <child link="kinect_rgb_link"/>
<!--<origin rpy="0.063486589917 0.013167017557 -0.045967491158" xyz="-0.066201837886 0.037212251149 0.031254947961"/>-->
    <origin rpy="0.063486589917 0.013167017557 -0.045967491158" xyz="-0.02 0.065 0.036254947961"/>
  </joint>
  <link name="kinect_rgb_link">
    <visual>
      <origin rpy="0 0 0" xyz="0 0 0"/>
      <geometry>
        <sphere radius="0.0005"/>
      </geometry>
    </visual>
  </link>
  <joint name="kinect_rgb_optical_frame_joint" type="fixed">
    <parent link="kinect_rgb_link"/>
    <child link="kinect_rgb_optical_frame"/>
    <origin rpy="-1.57 0 -1.57" xyz="0 0 0"/>
  </joint>
  <link name="kinect_rgb_optical_frame"/>
</robot>
