<?xml version="1.0" ?>
<robot xmlns:xacro="http://www.ros.org/wiki/xacro" name="generic_constructs">
	<!-- template block for material block -->
	<xacro:macro name="material_block" params="color_name rgba_vals">
		<material name="${color_name}">
			<color rgba="${rgba_vals}"/>
		</material>
	</xacro:macro>
	
	<!-- instantiated material blocks -->
	<xacro:material_block color_name="Blue" rgba_vals="0 0 1 1"/>
	<xacro:material_block color_name="Red" rgba_vals="1 0 0 1"/>
	<xacro:material_block color_name="Green" rgba_vals="0 1 0 1"/>
	<xacro:material_block color_name="Gray" rgba_vals="0.8 0.8 0.8 1"/>
	<xacro:material_block color_name="Yellow" rgba_vals="1 1 0 1"/>

	<!-- template block for inertial block -->
	<xacro:macro name="inertial_block" params="xyz_vals rpy_vals mass">
		<inertial>
			<origin xyz="${xyz_vals}" rpy="${rpy_vals}"/>
			<mass value="${mass}"/>
			<inertia ixx="1"  ixy="0"  ixz="0" iyy="1" iyz="0" izz="1"/>
		</inertial>
	</xacro:macro>

	<!-- template block for box shaped collision and visual subblocks -->
	<xacro:macro name="box_shape_sub_blocks" params="xyz_vals rpy_vals size_vals color_name">
		<origin xyz="${xyz_vals}" rpy="${rpy_vals}" />
		<geometry>
			<box size="${size_vals}" />
		</geometry>
		<material name="${color_name}" />
	</xacro:macro>

	<!-- template block for box visual block -->
	<xacro:macro name="box_visual_block" params="xyz rpy size color_name">
		<visual>
			<xacro:box_shape_sub_blocks xyz_vals="${xyz}" rpy_vals="${rpy}" size_vals="${size}" color_name="${color_name}"/>
		</visual>
	</xacro:macro>

	<!-- template block for box collision block -->
	<xacro:macro name="box_collision_block" params="xyz rpy size color_name">
		<collision>
			<xacro:box_shape_sub_blocks xyz_vals="${xyz}" rpy_vals="${rpy}" size_vals="${size}" color_name="${color_name}"/>
		</collision>
	</xacro:macro>

	<!-- template block for mesh collision and visual subblocks -->
	<xacro:macro name="mesh_shape_sub_blocks" params="xyz_vals rpy_vals mesh_refc color_name">
		<origin xyz="${xyz_vals}" rpy="${rpy_vals}"/>
		<geometry>
			<mesh filename="package://${mesh_refc}"/>
		</geometry>
		<material name="${color_name}"/>
	</xacro:macro>

	<!-- template block for fixed joints -->
	<xacro:macro name="fixed_joint" params="joint_name parent child xyz rpy">
		<joint name="${joint_name}" type="fixed">
			<origin xyz="${xyz}" rpy="${rpy}"/>
			<parent link="${parent}"/>
			<child link="${child}"/>
		</joint>
	</xacro:macro>

	<!-- template for prismatic joints -->
	<xacro:macro name="prismatic_joint" params="joint_name parent child xyz rpy xyz_a effr vel lw up">
		<joint name="${joint_name}" type="prismatic">
			<origin xyz="${xyz}" rpy="${rpy}"/>
			<parent link="${parent}"/>
			<child link="${child}"/>
			<axis xyz="${xyz_a}"/>
			<limit effort="${effr}" velocity="${vel}" lower="${lw}" upper="${up}"/>
		</joint>
	</xacro:macro>

	<!-- template block for revolute joints -->
	<xacro:macro name="revolute_joint" params="joint_name parent child xyz rpy xyz_a">
		<joint name="${joint_name}" type="revolute">
			<origin xyz="${xyz}" rpy="${rpy}"/>
			<parent link="${parent}"/>
			<child link="${child}"/>
			<axis xyz="${xyz_a}"/>
		</joint>
	</xacro:macro>
	<!-- template block link construct -->
	<xacro:macro name="link_construct" params="link_name *inertial_block *visual *collision">
		<link name="${link_name}">
			<xacro:insert_block name="inertial_block"/>
			<xacro:insert_block name="visual"/>
			<xacro:insert_block name="collision"/>
		</link>
	</xacro:macro>	
	<!-- template block for box link blocks -->
	<xacro:macro name="link_box_construct" params="link_name xyz_i rpy_i xyz_s rpy_s mass size">
		<link name="${link_name}">
			<xacro:inertial_block xyz_vals="${xyz_i}" rpy_vals="${rpy_i}" mass="${mass}"/>
			<visual>
				<xacro:box_shape_sub_blocks xyz_vals="${xyz_s}" rpy_vals="${rpy_s}" size_vals="${size}"
					color_name="Blue"/>
			</visual>
			<collision>
				<xacro:box_shape_sub_blocks xyz_vals="${xyz_s}" rpy_vals="${rpy_s}" size_vals="${size}"
					color_name="Yellow"/>
			</collision> 
		</link>
	</xacro:macro>
</robot>
