<?xml version="1.0" ?>
<robot name="MotomanSIA10D">
	<!-- link list -->
	<link name="motoman_base">
		<visual>
			<geometry>
				<mesh filename="package://MotomanSIA10D_Arm_Pkg/meshes/visual/Motoman/STL/HighResBinary/motoman_sia10d_base.STL" />
			</geometry>
			<material name="blue">
				<color rgba="0 0 1 1"/>
			</material>
		</visual>
		<collision>
			<geometry>
				<mesh filename="package://MotomanSIA10D_Arm_Pkg/meshes/collision/Motoman/SLT/LowResBinary/motoman_sia10d_base.stl" />
			</geometry>
			<material name="yellow">
				<color rgba="0 1 1 1"/>
			</material>
		</collision>
	</link>
	<link name="motoman_axis_s">
		<visual>
			<geometry>
				<mesh filename="package://MotomanSIA10D_Arm_Pkg/meshes/visual/Motoman/STL/HighResBinary/motoman_sia10d_axis_s.STL"/>
			</geometry>
			<material name="silver">
				<color rgba="0.8 0.8 0.8 1"/>
			</material>
		</visual>
		<collision>
			<geometry>
				<mesh filename="package://MotomanSIA10D_Arm_Pkg/meshes/collision/Motoman/SLT/LowResBinary/motoman_sia10d_axis_s.stl" />
			</geometry>
			<material name="yellow"/>
		</collision>
	</link>
	<link name="motoman_axis_l">
		<visual>
			<geometry>
				<mesh filename="package://MotomanSIA10D_Arm_Pkg/meshes/visual/Motoman/STL/HighResBinary/motoman_sia10d_axis_l.STL"/>
			</geometry>
			<material name="blue">
				<color rgba="0 0 1 1"/>
			</material>
		</visual>
		<collision>
			<geometry>
				<mesh filename="package://MotomanSIA10D_Arm_Pkg/meshes/collision/Motoman/SLT/LowResBinary/motoman_sia10d_axis_l.stl" />
			</geometry>
			<material name="yellow"/>
		</collision>
	</link>
	<link name="motoman_axis_e">
		<visual>
			<geometry>
				<mesh filename="package://MotomanSIA10D_Arm_Pkg/meshes/visual/Motoman/STL/HighResBinary/motoman_sia10d_axis_e.STL"/>
			</geometry>
			<material name="silver"/>
		</visual>
		<collision>
			<geometry>
				<mesh filename="package://MotomanSIA10D_Arm_Pkg/meshes/collision/Motoman/SLT/LowResBinary/motoman_sia10d_axis_e.stl" />
			</geometry>
			<material name="yellow"/>
		</collision>
	</link>
	<link name="motoman_axis_u">
		<visual>
			<geometry>
				<mesh filename="package://MotomanSIA10D_Arm_Pkg/meshes/visual/Motoman/STL/HighResBinary/motoman_sia10d_axis_u.STL"/>
			</geometry>
			<material name="blue"/>
		</visual>
		<collision>
			<geometry>
				<mesh filename="package://MotomanSIA10D_Arm_Pkg/meshes/collision/Motoman/SLT/LowResBinary/motoman_sia10d_axis_u.stl" />
			</geometry>
			<material name="yellow"/>
		</collision>
	</link>
	<link name="motoman_axis_r">
		<visual>
			<geometry>
				<mesh filename="package://MotomanSIA10D_Arm_Pkg/meshes/visual/Motoman/STL/HighResBinary/motoman_sia10d_axis_r.STL"/>
			</geometry>
			<material name="silver"/>
		</visual>
		<collision>
			<geometry>
				<mesh filename="package://MotomanSIA10D_Arm_Pkg/meshes/collision/Motoman/SLT/LowResBinary/motoman_sia10d_axis_r.stl" />
			</geometry>
			<material name="yellow"/>
		</collision>
	</link>
	<link name="motoman_axis_b">
		<visual>
			<geometry>
				<mesh filename="package://MotomanSIA10D_Arm_Pkg/meshes/visual/Motoman/STL/HighResBinary/motoman_sia10d_axis_b.STL"/>
			</geometry>
			<material name="blue"/>
		</visual>
		<collision>
			<geometry>
				<mesh filename="package://MotomanSIA10D_Arm_Pkg/meshes/collision/Motoman/SLT/LowResBinary/motoman_sia10d_axis_b.stl" />
			</geometry>
			<material name="yellow"/>
		</collision>
	</link>
	<link name="motoman_axis_t">
		<visual>
			<geometry>
				<mesh filename="package://MotomanSIA10D_Arm_Pkg/meshes/visual/Motoman/STL/HighResBinary/motoman_sia10d_axis_t.STL" />
			</geometry>
			<material name="silver"/>
		</visual>
		<collision>
			<geometry>
				<mesh filename="package://MotomanSIA10D_Arm_Pkg/meshes/collision/Motoman/SLT/LowResBinary/motoman_sia10d_axis_t.stl" />
			</geometry>
			<material name="yellow"/>
		</collision>
	</link>
	<!-- end of link list -->
	<!-- joint list -->
	<joint name="joint_s" type="revolute">
		<parent link="motoman_base"/>
		<child link="motoman_axis_s"/>
		<origin xyz="0 0 0.36" rpy="0 0 3.1415"/>
		<axis xyz="0 0 1" />
		<limit effort="1000.0" lower="-3.1415" upper="3.1415" velocity="100" />
	</joint>
	<joint name="joint_l" type="revolute">
		<parent link="motoman_axis_s"/>
		<child link="motoman_axis_l"/>
		<origin xyz="0 0 0" rpy="1.570 3.1416 0"/>
		<axis xyz="0 0 1" />
		<limit effort="1000.0" lower="-3.1416" upper="3.1416" velocity="100" />
	</joint>
	<joint name="joint_e" type="revolute">
		<parent link="motoman_axis_l"/>
		<child link="motoman_axis_e"/>
		<origin xyz="0 -0.36 0" rpy="1.570 0 0"/>
		<axis xyz="0 0 1" />
		<limit effort="1000.0" lower="-3.1416" upper="3.1416" velocity="100" />
	</joint>
	<joint name="joint_u" type="revolute">
		<parent link="motoman_axis_e"/>
		<child link="motoman_axis_u"/>
		<origin xyz="0 0 0" rpy="-1.570 0 0"/>
		<axis xyz="0 0 -1" />
		<limit effort="1000.0" lower="-3.1416" upper="3.1416" velocity="100" />
	</joint>
	<joint name="joint_r" type="revolute">
		<parent link="motoman_axis_u"/>
		<child link="motoman_axis_r"/>
		<origin xyz="0 -0.360 0" rpy="1.570 0 0"/>
		<axis xyz="0 0 -1" />
		<limit effort="1000.0" lower="-3.1416" upper="3.1416" velocity="100" />
	</joint>
	<joint name="joint_b" type="revolute">
		<parent link="motoman_axis_r"/>
		<child link="motoman_axis_b"/>
		<origin xyz="0 0 0" rpy="-1.570 0 0"/>
		<axis xyz="0 0 -1" />
		<limit effort="1000.0" lower="-3.1416" upper="3.1416" velocity="100" />
	</joint>
	<joint name="joint_t" type="revolute">
		<parent link="motoman_axis_b"/>
		<child link="motoman_axis_t"/>
		<origin xyz="0 -0.155 0" rpy="1.570 0 0"/>
		<axis xyz="0 0 -1" />
		<limit effort="1000.0" lower="-3.1416" upper="3.1416" velocity="100" />
	</joint>
	<!-- end of joint list -->
		
</robot>

